Watching for file changes with StatReloader
Exception in thread django-main-thread:
Traceback (most recent call last):
  File "/usr/lib/python3.5/threading.py", line 914, in _bootstrap_inner
    self.run()
  File "/usr/lib/python3.5/threading.py", line 862, in run
    self._target(*self._args, **self._kwargs)
  File "/home/abhinandan/PycharmProjects/todo/venv/lib/python3.5/site-packages/django/utils/autoreload.py", line 54, in wrapper
    fn(*args, **kwargs)
  File "/home/abhinandan/PycharmProjects/todo/venv/lib/python3.5/site-packages/django/core/management/commands/runserver.py", line 109, in inner_run
    autoreload.raise_last_exception()
  File "/home/abhinandan/PycharmProjects/todo/venv/lib/python3.5/site-packages/django/utils/autoreload.py", line 77, in raise_last_exception
    raise _exception[1]
  File "/home/abhinandan/PycharmProjects/todo/venv/lib/python3.5/site-packages/django/core/management/__init__.py", line 337, in execute
    autoreload.check_errors(django.setup)()
  File "/home/abhinandan/PycharmProjects/todo/venv/lib/python3.5/site-packages/django/utils/autoreload.py", line 54, in wrapper
    fn(*args, **kwargs)
  File "/home/abhinandan/PycharmProjects/todo/venv/lib/python3.5/site-packages/django/__init__.py", line 24, in setup
    apps.populate(settings.INSTALLED_APPS)
  File "/home/abhinandan/PycharmProjects/todo/venv/lib/python3.5/site-packages/django/apps/registry.py", line 95, in populate
    "duplicates: %s" % app_config.label)
django.core.exceptions.ImproperlyConfigured: Application labels aren't unique, duplicates: todo_list

/home/abhinandan/PycharmProjects/todo/todo/settings.py changed, reloading.
Watching for file changes with StatReloader
Exception in thread django-main-thread:
Traceback (most recent call last):
  File "/usr/lib/python3.5/threading.py", line 914, in _bootstrap_inner
    self.run()
  File "/usr/lib/python3.5/threading.py", line 862, in run
    self._target(*self._args, **self._kwargs)
  File "/home/abhinandan/PycharmProjects/todo/venv/lib/python3.5/site-packages/django/utils/autoreload.py", line 54, in wrapper
    fn(*args, **kwargs)
  File "/home/abhinandan/PycharmProjects/todo/venv/lib/python3.5/site-packages/django/core/management/commands/runserver.py", line 117, in inner_run
    self.check(display_num_errors=True)
  File "/home/abhinandan/PycharmProjects/todo/venv/lib/python3.5/site-packages/django/core/management/base.py", line 390, in check
    include_deployment_checks=include_deployment_checks,
  File "/home/abhinandan/PycharmProjects/todo/venv/lib/python3.5/site-packages/django/core/management/base.py", line 377, in _run_checks
    return checks.run_checks(**kwargs)
  File "/home/abhinandan/PycharmProjects/todo/venv/lib/python3.5/site-packages/django/core/checks/registry.py", line 72, in run_checks
    new_errors = check(app_configs=app_configs)
  File "/home/abhinandan/PycharmProjects/todo/venv/lib/python3.5/site-packages/django/core/checks/urls.py", line 40, in check_url_namespaces_unique
    all_namespaces = _load_all_namespaces(resolver)
  File "/home/abhinandan/PycharmProjects/todo/venv/lib/python3.5/site-packages/django/core/checks/urls.py", line 57, in _load_all_namespaces
    url_patterns = getattr(resolver, 'url_patterns', [])
  File "/home/abhinandan/PycharmProjects/todo/venv/lib/python3.5/site-packages/django/utils/functional.py", line 80, in __get__
    res = instance.__dict__[self.name] = self.func(instance)
  File "/home/abhinandan/PycharmProjects/todo/venv/lib/python3.5/site-packages/django/urls/resolvers.py", line 579, in url_patterns
    patterns = getattr(self.urlconf_module, "urlpatterns", self.urlconf_module)
  File "/home/abhinandan/PycharmProjects/todo/venv/lib/python3.5/site-packages/django/utils/functional.py", line 80, in __get__
    res = instance.__dict__[self.name] = self.func(instance)
  File "/home/abhinandan/PycharmProjects/todo/venv/lib/python3.5/site-packages/django/urls/resolvers.py", line 572, in urlconf_module
    return import_module(self.urlconf_name)
  File "/usr/lib/python3.5/importlib/__init__.py", line 126, in import_module
    return _bootstrap._gcd_import(name[level:], package, level)
  File "<frozen importlib._bootstrap>", line 986, in _gcd_import
  File "<frozen importlib._bootstrap>", line 969, in _find_and_load
  File "<frozen importlib._bootstrap>", line 958, in _find_and_load_unlocked
  File "<frozen importlib._bootstrap>", line 673, in _load_unlocked
  File "<frozen importlib._bootstrap_external>", line 665, in exec_module
  File "<frozen importlib._bootstrap>", line 222, in _call_with_frames_removed
  File "/home/abhinandan/PycharmProjects/todo/todo/urls.py", line 22, in <module>
    path('',include('todo_list.urls'))
  File "/home/abhinandan/PycharmProjects/todo/venv/lib/python3.5/site-packages/django/urls/conf.py", line 34, in include
    urlconf_module = import_module(urlconf_module)
  File "/usr/lib/python3.5/importlib/__init__.py", line 126, in import_module
    return _bootstrap._gcd_import(name[level:], package, level)
  File "<frozen importlib._bootstrap>", line 986, in _gcd_import
  File "<frozen importlib._bootstrap>", line 969, in _find_and_load
  File "<frozen importlib._bootstrap>", line 958, in _find_and_load_unlocked
  File "<frozen importlib._bootstrap>", line 673, in _load_unlocked
  File "<frozen importlib._bootstrap_external>", line 665, in exec_module
  File "<frozen importlib._bootstrap>", line 222, in _call_with_frames_removed
  File "/home/abhinandan/PycharmProjects/todo/todo_list/urls.py", line 5, in <module>
    path('',views.home,name=home)
NameError: name 'home' is not defined

/home/abhinandan/PycharmProjects/todo/todo_list/urls.py changed, reloading.
Performing system checks...

Watching for file changes with StatReloader
Watching for file changes with StatReloader
[07/Aug/2019 08:19:10] "GET / HTTP/1.1" 200 135
[07/Aug/2019 08:22:53] "GET / HTTP/1.1" 200 143
[07/Aug/2019 08:26:30] "GET / HTTP/1.1" 200 1272
[07/Aug/2019 08:30:24] "GET / HTTP/1.1" 200 3206
[07/Aug/2019 08:32:32] "GET / HTTP/1.1" 200 2343
[07/Aug/2019 08:33:05] "GET / HTTP/1.1" 200 2075
[07/Aug/2019 08:33:53] "GET / HTTP/1.1" 200 2187
[07/Aug/2019 08:34:48] "GET / HTTP/1.1" 200 2203
/home/abhinandan/PycharmProjects/todo/todo_list/models.py changed, reloading.
Performing system checks...

System check identified no issues (0 silenced).

You have 17 unapplied migration(s). Your project may not work properly until you apply the migrations for app(s): admin, auth, contenttypes, sessions.
Run 'python manage.py migrate' to apply them.
August 07, 2019 - 08:19:08
Django version 2.2.4, using settings 'todo.settings'
Starting development server at http://127.0.0.1:7000/
Quit the server with CONTROL-C.
Watching for file changes with StatReloader
/home/abhinandan/PycharmProjects/todo/todo_list/models.py changed, reloading.
Performing system checks...

System check identified no issues (0 silenced).
August 07, 2019 - 08:37:15
Django version 2.2.4, using settings 'todo.settings'
Starting development server at http://127.0.0.1:7000/
Quit the server with CONTROL-C.
Watching for file changes with StatReloader
Exception in thread django-main-thread:
Traceback (most recent call last):
  File "/usr/lib/python3.5/threading.py", line 914, in _bootstrap_inner
    self.run()
  File "/usr/lib/python3.5/threading.py", line 862, in run
    self._target(*self._args, **self._kwargs)
  File "/home/abhinandan/PycharmProjects/todo/venv/lib/python3.5/site-packages/django/utils/autoreload.py", line 54, in wrapper
    fn(*args, **kwargs)
  File "/home/abhinandan/PycharmProjects/todo/venv/lib/python3.5/site-packages/django/core/management/commands/runserver.py", line 109, in inner_run
    autoreload.raise_last_exception()
  File "/home/abhinandan/PycharmProjects/todo/venv/lib/python3.5/site-packages/django/utils/autoreload.py", line 77, in raise_last_exception
    raise _exception[1]
  File "/home/abhinandan/PycharmProjects/todo/venv/lib/python3.5/site-packages/django/core/management/__init__.py", line 337, in execute
    autoreload.check_errors(django.setup)()
  File "/home/abhinandan/PycharmProjects/todo/venv/lib/python3.5/site-packages/django/utils/autoreload.py", line 54, in wrapper
    fn(*args, **kwargs)
  File "/home/abhinandan/PycharmProjects/todo/venv/lib/python3.5/site-packages/django/__init__.py", line 24, in setup
    apps.populate(settings.INSTALLED_APPS)
  File "/home/abhinandan/PycharmProjects/todo/venv/lib/python3.5/site-packages/django/apps/registry.py", line 114, in populate
    app_config.import_models()
  File "/home/abhinandan/PycharmProjects/todo/venv/lib/python3.5/site-packages/django/apps/config.py", line 211, in import_models
    self.models_module = import_module(models_module_name)
  File "/usr/lib/python3.5/importlib/__init__.py", line 126, in import_module
    return _bootstrap._gcd_import(name[level:], package, level)
  File "<frozen importlib._bootstrap>", line 986, in _gcd_import
  File "<frozen importlib._bootstrap>", line 969, in _find_and_load
  File "<frozen importlib._bootstrap>", line 958, in _find_and_load_unlocked
  File "<frozen importlib._bootstrap>", line 673, in _load_unlocked
  File "<frozen importlib._bootstrap_external>", line 661, in exec_module
  File "<frozen importlib._bootstrap_external>", line 767, in get_code
  File "<frozen importlib._bootstrap_external>", line 727, in source_to_code
  File "<frozen importlib._bootstrap>", line 222, in _call_with_frames_removed
  File "/home/abhinandan/PycharmProjects/todo/todo_list/models.py", line 3
    class List(models.Model):
                            ^
SyntaxError: unexpected EOF while parsing

/home/abhinandan/PycharmProjects/todo/todo_list/models.py changed, reloading.
Watching for file changes with StatReloader
Exception in thread django-main-thread:
Traceback (most recent call last):
  File "/usr/lib/python3.5/threading.py", line 914, in _bootstrap_inner
    self.run()
  File "/usr/lib/python3.5/threading.py", line 862, in run
    self._target(*self._args, **self._kwargs)
  File "/home/abhinandan/PycharmProjects/todo/venv/lib/python3.5/site-packages/django/utils/autoreload.py", line 54, in wrapper
    fn(*args, **kwargs)
  File "/home/abhinandan/PycharmProjects/todo/venv/lib/python3.5/site-packages/django/core/management/commands/runserver.py", line 109, in inner_run
    autoreload.raise_last_exception()
  File "/home/abhinandan/PycharmProjects/todo/venv/lib/python3.5/site-packages/django/utils/autoreload.py", line 77, in raise_last_exception
    raise _exception[1]
  File "/home/abhinandan/PycharmProjects/todo/venv/lib/python3.5/site-packages/django/core/management/__init__.py", line 337, in execute
    autoreload.check_errors(django.setup)()
  File "/home/abhinandan/PycharmProjects/todo/venv/lib/python3.5/site-packages/django/utils/autoreload.py", line 54, in wrapper
    fn(*args, **kwargs)
  File "/home/abhinandan/PycharmProjects/todo/venv/lib/python3.5/site-packages/django/__init__.py", line 24, in setup
    apps.populate(settings.INSTALLED_APPS)
  File "/home/abhinandan/PycharmProjects/todo/venv/lib/python3.5/site-packages/django/apps/registry.py", line 114, in populate
    app_config.import_models()
  File "/home/abhinandan/PycharmProjects/todo/venv/lib/python3.5/site-packages/django/apps/config.py", line 211, in import_models
    self.models_module = import_module(models_module_name)
  File "/usr/lib/python3.5/importlib/__init__.py", line 126, in import_module
    return _bootstrap._gcd_import(name[level:], package, level)
  File "<frozen importlib._bootstrap>", line 986, in _gcd_import
  File "<frozen importlib._bootstrap>", line 969, in _find_and_load
  File "<frozen importlib._bootstrap>", line 958, in _find_and_load_unlocked
  File "<frozen importlib._bootstrap>", line 673, in _load_unlocked
  File "<frozen importlib._bootstrap_external>", line 661, in exec_module
  File "<frozen importlib._bootstrap_external>", line 767, in get_code
  File "<frozen importlib._bootstrap_external>", line 727, in source_to_code
  File "<frozen importlib._bootstrap>", line 222, in _call_with_frames_removed
  File "/home/abhinandan/PycharmProjects/todo/todo_list/models.py", line 4
    item =
          ^
SyntaxError: invalid syntax

/home/abhinandan/PycharmProjects/todo/todo_list/models.py changed, reloading.
Watching for file changes with StatReloader
/home/abhinandan/PycharmProjects/todo/todo_list/models.py changed, reloading.
Performing system checks...

System check identified no issues (0 silenced).
August 07, 2019 - 08:37:50
Django version 2.2.4, using settings 'todo.settings'
Starting development server at http://127.0.0.1:7000/
Quit the server with CONTROL-C.
Watching for file changes with StatReloader
/home/abhinandan/PycharmProjects/todo/todo_list/models.py changed, reloading.
Performing system checks...

System check identified no issues (0 silenced).
August 07, 2019 - 08:38:00
Django version 2.2.4, using settings 'todo.settings'
Starting development server at http://127.0.0.1:7000/
Quit the server with CONTROL-C.
Watching for file changes with StatReloader
/home/abhinandan/PycharmProjects/todo/todo_list/models.py changed, reloading.
Performing system checks...

System check identified no issues (0 silenced).
August 07, 2019 - 08:38:14
Django version 2.2.4, using settings 'todo.settings'
Starting development server at http://127.0.0.1:7000/
Quit the server with CONTROL-C.
Watching for file changes with StatReloader
/home/abhinandan/PycharmProjects/todo/todo_list/models.py changed, reloading.
Performing system checks...

System check identified no issues (0 silenced).
August 07, 2019 - 08:38:23
Django version 2.2.4, using settings 'todo.settings'
Starting development server at http://127.0.0.1:7000/
Quit the server with CONTROL-C.
Watching for file changes with StatReloader
Exception in thread django-main-thread:
Traceback (most recent call last):
  File "/usr/lib/python3.5/threading.py", line 914, in _bootstrap_inner
    self.run()
  File "/usr/lib/python3.5/threading.py", line 862, in run
    self._target(*self._args, **self._kwargs)
  File "/home/abhinandan/PycharmProjects/todo/venv/lib/python3.5/site-packages/django/utils/autoreload.py", line 54, in wrapper
    fn(*args, **kwargs)
  File "/home/abhinandan/PycharmProjects/todo/venv/lib/python3.5/site-packages/django/core/management/commands/runserver.py", line 109, in inner_run
    autoreload.raise_last_exception()
  File "/home/abhinandan/PycharmProjects/todo/venv/lib/python3.5/site-packages/django/utils/autoreload.py", line 77, in raise_last_exception
    raise _exception[1]
  File "/home/abhinandan/PycharmProjects/todo/venv/lib/python3.5/site-packages/django/core/management/__init__.py", line 337, in execute
    autoreload.check_errors(django.setup)()
  File "/home/abhinandan/PycharmProjects/todo/venv/lib/python3.5/site-packages/django/utils/autoreload.py", line 54, in wrapper
    fn(*args, **kwargs)
  File "/home/abhinandan/PycharmProjects/todo/venv/lib/python3.5/site-packages/django/__init__.py", line 24, in setup
    apps.populate(settings.INSTALLED_APPS)
  File "/home/abhinandan/PycharmProjects/todo/venv/lib/python3.5/site-packages/django/apps/registry.py", line 114, in populate
    app_config.import_models()
  File "/home/abhinandan/PycharmProjects/todo/venv/lib/python3.5/site-packages/django/apps/config.py", line 211, in import_models
    self.models_module = import_module(models_module_name)
  File "/usr/lib/python3.5/importlib/__init__.py", line 126, in import_module
    return _bootstrap._gcd_import(name[level:], package, level)
  File "<frozen importlib._bootstrap>", line 986, in _gcd_import
  File "<frozen importlib._bootstrap>", line 969, in _find_and_load
  File "<frozen importlib._bootstrap>", line 958, in _find_and_load_unlocked
  File "<frozen importlib._bootstrap>", line 673, in _load_unlocked
  File "<frozen importlib._bootstrap_external>", line 661, in exec_module
  File "<frozen importlib._bootstrap_external>", line 767, in get_code
  File "<frozen importlib._bootstrap_external>", line 727, in source_to_code
  File "<frozen importlib._bootstrap>", line 222, in _call_with_frames_removed
  File "/home/abhinandan/PycharmProjects/todo/todo_list/models.py", line 8
    
    ^
SyntaxError: unexpected EOF while parsing

/home/abhinandan/PycharmProjects/todo/todo_list/models.py changed, reloading.
Watching for file changes with StatReloader
Exception in thread django-main-thread:
Traceback (most recent call last):
  File "/usr/lib/python3.5/threading.py", line 914, in _bootstrap_inner
    self.run()
  File "/usr/lib/python3.5/threading.py", line 862, in run
    self._target(*self._args, **self._kwargs)
  File "/home/abhinandan/PycharmProjects/todo/venv/lib/python3.5/site-packages/django/utils/autoreload.py", line 54, in wrapper
    fn(*args, **kwargs)
  File "/home/abhinandan/PycharmProjects/todo/venv/lib/python3.5/site-packages/django/core/management/commands/runserver.py", line 109, in inner_run
    autoreload.raise_last_exception()
  File "/home/abhinandan/PycharmProjects/todo/venv/lib/python3.5/site-packages/django/utils/autoreload.py", line 77, in raise_last_exception
    raise _exception[1]
  File "/home/abhinandan/PycharmProjects/todo/venv/lib/python3.5/site-packages/django/core/management/__init__.py", line 337, in execute
    autoreload.check_errors(django.setup)()
  File "/home/abhinandan/PycharmProjects/todo/venv/lib/python3.5/site-packages/django/utils/autoreload.py", line 54, in wrapper
    fn(*args, **kwargs)
  File "/home/abhinandan/PycharmProjects/todo/venv/lib/python3.5/site-packages/django/__init__.py", line 24, in setup
    apps.populate(settings.INSTALLED_APPS)
  File "/home/abhinandan/PycharmProjects/todo/venv/lib/python3.5/site-packages/django/apps/registry.py", line 114, in populate
    app_config.import_models()
  File "/home/abhinandan/PycharmProjects/todo/venv/lib/python3.5/site-packages/django/apps/config.py", line 211, in import_models
    self.models_module = import_module(models_module_name)
  File "/usr/lib/python3.5/importlib/__init__.py", line 126, in import_module
    return _bootstrap._gcd_import(name[level:], package, level)
  File "<frozen importlib._bootstrap>", line 986, in _gcd_import
  File "<frozen importlib._bootstrap>", line 969, in _find_and_load
  File "<frozen importlib._bootstrap>", line 958, in _find_and_load_unlocked
  File "<frozen importlib._bootstrap>", line 673, in _load_unlocked
  File "<frozen importlib._bootstrap_external>", line 661, in exec_module
  File "<frozen importlib._bootstrap_external>", line 767, in get_code
  File "<frozen importlib._bootstrap_external>", line 727, in source_to_code
  File "<frozen importlib._bootstrap>", line 222, in _call_with_frames_removed
  File "/home/abhinandan/PycharmProjects/todo/todo_list/models.py", line 8
    return self.
               ^
SyntaxError: invalid syntax

/home/abhinandan/PycharmProjects/todo/todo_list/models.py changed, reloading.
Watching for file changes with StatReloader
/home/abhinandan/PycharmProjects/todo/todo_list/models.py changed, reloading.
Performing system checks...

System check identified no issues (0 silenced).
August 07, 2019 - 08:38:45
Django version 2.2.4, using settings 'todo.settings'
Starting development server at http://127.0.0.1:7000/
Quit the server with CONTROL-C.
Watching for file changes with StatReloader
/home/abhinandan/PycharmProjects/todo/todo_list/models.py changed, reloading.
Performing system checks...

System check identified no issues (0 silenced).
August 07, 2019 - 08:38:57
Django version 2.2.4, using settings 'todo.settings'
Starting development server at http://127.0.0.1:7000/
Quit the server with CONTROL-C.
Watching for file changes with StatReloader
/home/abhinandan/PycharmProjects/todo/todo_list/models.py changed, reloading.
Performing system checks...

System check identified no issues (0 silenced).
August 07, 2019 - 08:39:08
Django version 2.2.4, using settings 'todo.settings'
Starting development server at http://127.0.0.1:7000/
Quit the server with CONTROL-C.
Watching for file changes with StatReloader
/home/abhinandan/PycharmProjects/todo/todo_list/views.py changed, reloading.
Performing system checks...

System check identified no issues (0 silenced).
August 07, 2019 - 08:39:28
Django version 2.2.4, using settings 'todo.settings'
Starting development server at http://127.0.0.1:7000/
Quit the server with CONTROL-C.
Watching for file changes with StatReloader
/home/abhinandan/PycharmProjects/todo/todo_list/views.py changed, reloading.
Performing system checks...

System check identified no issues (0 silenced).
August 07, 2019 - 08:40:48
Django version 2.2.4, using settings 'todo.settings'
Starting development server at http://127.0.0.1:7000/
Quit the server with CONTROL-C.
Watching for file changes with StatReloader
/home/abhinandan/PycharmProjects/todo/todo_list/views.py changed, reloading.
Performing system checks...

System check identified no issues (0 silenced).
August 07, 2019 - 08:43:38
Django version 2.2.4, using settings 'todo.settings'
Starting development server at http://127.0.0.1:7000/
Quit the server with CONTROL-C.
Watching for file changes with StatReloader
/home/abhinandan/PycharmProjects/todo/todo_list/views.py changed, reloading.
Performing system checks...

System check identified no issues (0 silenced).
August 07, 2019 - 08:44:00
Django version 2.2.4, using settings 'todo.settings'
Starting development server at http://127.0.0.1:7000/
Quit the server with CONTROL-C.
Watching for file changes with StatReloader
/home/abhinandan/PycharmProjects/todo/todo_list/views.py changed, reloading.
Performing system checks...

System check identified no issues (0 silenced).
August 07, 2019 - 08:44:10
Django version 2.2.4, using settings 'todo.settings'
Starting development server at http://127.0.0.1:7000/
Quit the server with CONTROL-C.
Watching for file changes with StatReloader
Exception in thread django-main-thread:
Traceback (most recent call last):
  File "/usr/lib/python3.5/threading.py", line 914, in _bootstrap_inner
    self.run()
  File "/usr/lib/python3.5/threading.py", line 862, in run
    self._target(*self._args, **self._kwargs)
  File "/home/abhinandan/PycharmProjects/todo/venv/lib/python3.5/site-packages/django/utils/autoreload.py", line 54, in wrapper
    fn(*args, **kwargs)
  File "/home/abhinandan/PycharmProjects/todo/venv/lib/python3.5/site-packages/django/core/management/commands/runserver.py", line 117, in inner_run
    self.check(display_num_errors=True)
  File "/home/abhinandan/PycharmProjects/todo/venv/lib/python3.5/site-packages/django/core/management/base.py", line 390, in check
    include_deployment_checks=include_deployment_checks,
  File "/home/abhinandan/PycharmProjects/todo/venv/lib/python3.5/site-packages/django/core/management/base.py", line 377, in _run_checks
    return checks.run_checks(**kwargs)
  File "/home/abhinandan/PycharmProjects/todo/venv/lib/python3.5/site-packages/django/core/checks/registry.py", line 72, in run_checks
    new_errors = check(app_configs=app_configs)
  File "/home/abhinandan/PycharmProjects/todo/venv/lib/python3.5/site-packages/django/core/checks/urls.py", line 40, in check_url_namespaces_unique
    all_namespaces = _load_all_namespaces(resolver)
  File "/home/abhinandan/PycharmProjects/todo/venv/lib/python3.5/site-packages/django/core/checks/urls.py", line 57, in _load_all_namespaces
    url_patterns = getattr(resolver, 'url_patterns', [])
  File "/home/abhinandan/PycharmProjects/todo/venv/lib/python3.5/site-packages/django/utils/functional.py", line 80, in __get__
    res = instance.__dict__[self.name] = self.func(instance)
  File "/home/abhinandan/PycharmProjects/todo/venv/lib/python3.5/site-packages/django/urls/resolvers.py", line 579, in url_patterns
    patterns = getattr(self.urlconf_module, "urlpatterns", self.urlconf_module)
  File "/home/abhinandan/PycharmProjects/todo/venv/lib/python3.5/site-packages/django/utils/functional.py", line 80, in __get__
    res = instance.__dict__[self.name] = self.func(instance)
  File "/home/abhinandan/PycharmProjects/todo/venv/lib/python3.5/site-packages/django/urls/resolvers.py", line 572, in urlconf_module
    return import_module(self.urlconf_name)
  File "/usr/lib/python3.5/importlib/__init__.py", line 126, in import_module
    return _bootstrap._gcd_import(name[level:], package, level)
  File "<frozen importlib._bootstrap>", line 986, in _gcd_import
  File "<frozen importlib._bootstrap>", line 969, in _find_and_load
  File "<frozen importlib._bootstrap>", line 958, in _find_and_load_unlocked
  File "<frozen importlib._bootstrap>", line 673, in _load_unlocked
  File "<frozen importlib._bootstrap_external>", line 665, in exec_module
  File "<frozen importlib._bootstrap>", line 222, in _call_with_frames_removed
  File "/home/abhinandan/PycharmProjects/todo/todo/urls.py", line 18, in <module>
    from todo_list import views
  File "/home/abhinandan/PycharmProjects/todo/todo_list/views.py", line 7
    if request.method == ''
                          ^
SyntaxError: invalid syntax

/home/abhinandan/PycharmProjects/todo/todo_list/views.py changed, reloading.
Performing system checks...

Watching for file changes with StatReloader
Exception in thread django-main-thread:
Traceback (most recent call last):
  File "/usr/lib/python3.5/threading.py", line 914, in _bootstrap_inner
    self.run()
  File "/usr/lib/python3.5/threading.py", line 862, in run
    self._target(*self._args, **self._kwargs)
  File "/home/abhinandan/PycharmProjects/todo/venv/lib/python3.5/site-packages/django/utils/autoreload.py", line 54, in wrapper
    fn(*args, **kwargs)
  File "/home/abhinandan/PycharmProjects/todo/venv/lib/python3.5/site-packages/django/core/management/commands/runserver.py", line 117, in inner_run
    self.check(display_num_errors=True)
  File "/home/abhinandan/PycharmProjects/todo/venv/lib/python3.5/site-packages/django/core/management/base.py", line 390, in check
    include_deployment_checks=include_deployment_checks,
  File "/home/abhinandan/PycharmProjects/todo/venv/lib/python3.5/site-packages/django/core/management/base.py", line 377, in _run_checks
    return checks.run_checks(**kwargs)
  File "/home/abhinandan/PycharmProjects/todo/venv/lib/python3.5/site-packages/django/core/checks/registry.py", line 72, in run_checks
    new_errors = check(app_configs=app_configs)
  File "/home/abhinandan/PycharmProjects/todo/venv/lib/python3.5/site-packages/django/core/checks/urls.py", line 40, in check_url_namespaces_unique
    all_namespaces = _load_all_namespaces(resolver)
  File "/home/abhinandan/PycharmProjects/todo/venv/lib/python3.5/site-packages/django/core/checks/urls.py", line 57, in _load_all_namespaces
    url_patterns = getattr(resolver, 'url_patterns', [])
  File "/home/abhinandan/PycharmProjects/todo/venv/lib/python3.5/site-packages/django/utils/functional.py", line 80, in __get__
    res = instance.__dict__[self.name] = self.func(instance)
  File "/home/abhinandan/PycharmProjects/todo/venv/lib/python3.5/site-packages/django/urls/resolvers.py", line 579, in url_patterns
    patterns = getattr(self.urlconf_module, "urlpatterns", self.urlconf_module)
  File "/home/abhinandan/PycharmProjects/todo/venv/lib/python3.5/site-packages/django/utils/functional.py", line 80, in __get__
    res = instance.__dict__[self.name] = self.func(instance)
  File "/home/abhinandan/PycharmProjects/todo/venv/lib/python3.5/site-packages/django/urls/resolvers.py", line 572, in urlconf_module
    return import_module(self.urlconf_name)
  File "/usr/lib/python3.5/importlib/__init__.py", line 126, in import_module
    return _bootstrap._gcd_import(name[level:], package, level)
  File "<frozen importlib._bootstrap>", line 986, in _gcd_import
  File "<frozen importlib._bootstrap>", line 969, in _find_and_load
  File "<frozen importlib._bootstrap>", line 958, in _find_and_load_unlocked
  File "<frozen importlib._bootstrap>", line 673, in _load_unlocked
  File "<frozen importlib._bootstrap_external>", line 665, in exec_module
  File "<frozen importlib._bootstrap>", line 222, in _call_with_frames_removed
  File "/home/abhinandan/PycharmProjects/todo/todo/urls.py", line 18, in <module>
    from todo_list import views
  File "/home/abhinandan/PycharmProjects/todo/todo_list/views.py", line 7
    if request.method == 'POST'
                              ^
SyntaxError: invalid syntax

/home/abhinandan/PycharmProjects/todo/todo_list/views.py changed, reloading.
Performing system checks...

Watching for file changes with StatReloader
Exception in thread django-main-thread:
Traceback (most recent call last):
  File "/usr/lib/python3.5/threading.py", line 914, in _bootstrap_inner
    self.run()
  File "/usr/lib/python3.5/threading.py", line 862, in run
    self._target(*self._args, **self._kwargs)
  File "/home/abhinandan/PycharmProjects/todo/venv/lib/python3.5/site-packages/django/utils/autoreload.py", line 54, in wrapper
    fn(*args, **kwargs)
  File "/home/abhinandan/PycharmProjects/todo/venv/lib/python3.5/site-packages/django/core/management/commands/runserver.py", line 117, in inner_run
    self.check(display_num_errors=True)
  File "/home/abhinandan/PycharmProjects/todo/venv/lib/python3.5/site-packages/django/core/management/base.py", line 390, in check
    include_deployment_checks=include_deployment_checks,
  File "/home/abhinandan/PycharmProjects/todo/venv/lib/python3.5/site-packages/django/core/management/base.py", line 377, in _run_checks
    return checks.run_checks(**kwargs)
  File "/home/abhinandan/PycharmProjects/todo/venv/lib/python3.5/site-packages/django/core/checks/registry.py", line 72, in run_checks
    new_errors = check(app_configs=app_configs)
  File "/home/abhinandan/PycharmProjects/todo/venv/lib/python3.5/site-packages/django/core/checks/urls.py", line 40, in check_url_namespaces_unique
    all_namespaces = _load_all_namespaces(resolver)
  File "/home/abhinandan/PycharmProjects/todo/venv/lib/python3.5/site-packages/django/core/checks/urls.py", line 57, in _load_all_namespaces
    url_patterns = getattr(resolver, 'url_patterns', [])
  File "/home/abhinandan/PycharmProjects/todo/venv/lib/python3.5/site-packages/django/utils/functional.py", line 80, in __get__
    res = instance.__dict__[self.name] = self.func(instance)
  File "/home/abhinandan/PycharmProjects/todo/venv/lib/python3.5/site-packages/django/urls/resolvers.py", line 579, in url_patterns
    patterns = getattr(self.urlconf_module, "urlpatterns", self.urlconf_module)
  File "/home/abhinandan/PycharmProjects/todo/venv/lib/python3.5/site-packages/django/utils/functional.py", line 80, in __get__
    res = instance.__dict__[self.name] = self.func(instance)
  File "/home/abhinandan/PycharmProjects/todo/venv/lib/python3.5/site-packages/django/urls/resolvers.py", line 572, in urlconf_module
    return import_module(self.urlconf_name)
  File "/usr/lib/python3.5/importlib/__init__.py", line 126, in import_module
    return _bootstrap._gcd_import(name[level:], package, level)
  File "<frozen importlib._bootstrap>", line 986, in _gcd_import
  File "<frozen importlib._bootstrap>", line 969, in _find_and_load
  File "<frozen importlib._bootstrap>", line 958, in _find_and_load_unlocked
  File "<frozen importlib._bootstrap>", line 673, in _load_unlocked
  File "<frozen importlib._bootstrap_external>", line 665, in exec_module
  File "<frozen importlib._bootstrap>", line 222, in _call_with_frames_removed
  File "/home/abhinandan/PycharmProjects/todo/todo/urls.py", line 18, in <module>
    from todo_list import views
  File "/home/abhinandan/PycharmProjects/todo/todo_list/views.py", line 9
    return render(request,"home.html",{})
         ^
IndentationError: expected an indented block

/home/abhinandan/PycharmProjects/todo/todo_list/views.py changed, reloading.
Performing system checks...

Watching for file changes with StatReloader
Exception in thread django-main-thread:
Traceback (most recent call last):
  File "/usr/lib/python3.5/threading.py", line 914, in _bootstrap_inner
    self.run()
  File "/usr/lib/python3.5/threading.py", line 862, in run
    self._target(*self._args, **self._kwargs)
  File "/home/abhinandan/PycharmProjects/todo/venv/lib/python3.5/site-packages/django/utils/autoreload.py", line 54, in wrapper
    fn(*args, **kwargs)
  File "/home/abhinandan/PycharmProjects/todo/venv/lib/python3.5/site-packages/django/core/management/commands/runserver.py", line 117, in inner_run
    self.check(display_num_errors=True)
  File "/home/abhinandan/PycharmProjects/todo/venv/lib/python3.5/site-packages/django/core/management/base.py", line 390, in check
    include_deployment_checks=include_deployment_checks,
  File "/home/abhinandan/PycharmProjects/todo/venv/lib/python3.5/site-packages/django/core/management/base.py", line 377, in _run_checks
    return checks.run_checks(**kwargs)
  File "/home/abhinandan/PycharmProjects/todo/venv/lib/python3.5/site-packages/django/core/checks/registry.py", line 72, in run_checks
    new_errors = check(app_configs=app_configs)
  File "/home/abhinandan/PycharmProjects/todo/venv/lib/python3.5/site-packages/django/core/checks/urls.py", line 40, in check_url_namespaces_unique
    all_namespaces = _load_all_namespaces(resolver)
  File "/home/abhinandan/PycharmProjects/todo/venv/lib/python3.5/site-packages/django/core/checks/urls.py", line 57, in _load_all_namespaces
    url_patterns = getattr(resolver, 'url_patterns', [])
  File "/home/abhinandan/PycharmProjects/todo/venv/lib/python3.5/site-packages/django/utils/functional.py", line 80, in __get__
    res = instance.__dict__[self.name] = self.func(instance)
  File "/home/abhinandan/PycharmProjects/todo/venv/lib/python3.5/site-packages/django/urls/resolvers.py", line 579, in url_patterns
    patterns = getattr(self.urlconf_module, "urlpatterns", self.urlconf_module)
  File "/home/abhinandan/PycharmProjects/todo/venv/lib/python3.5/site-packages/django/utils/functional.py", line 80, in __get__
    res = instance.__dict__[self.name] = self.func(instance)
  File "/home/abhinandan/PycharmProjects/todo/venv/lib/python3.5/site-packages/django/urls/resolvers.py", line 572, in urlconf_module
    return import_module(self.urlconf_name)
  File "/usr/lib/python3.5/importlib/__init__.py", line 126, in import_module
    return _bootstrap._gcd_import(name[level:], package, level)
  File "<frozen importlib._bootstrap>", line 986, in _gcd_import
  File "<frozen importlib._bootstrap>", line 969, in _find_and_load
  File "<frozen importlib._bootstrap>", line 958, in _find_and_load_unlocked
  File "<frozen importlib._bootstrap>", line 673, in _load_unlocked
  File "<frozen importlib._bootstrap_external>", line 665, in exec_module
  File "<frozen importlib._bootstrap>", line 222, in _call_with_frames_removed
  File "/home/abhinandan/PycharmProjects/todo/todo/urls.py", line 18, in <module>
    from todo_list import views
  File "/home/abhinandan/PycharmProjects/todo/todo_list/views.py", line 8
    form =
          ^
SyntaxError: invalid syntax

/home/abhinandan/PycharmProjects/todo/todo_list/views.py changed, reloading.
Performing system checks...

Watching for file changes with StatReloader
/home/abhinandan/PycharmProjects/todo/todo_list/views.py changed, reloading.
Performing system checks...

System check identified no issues (0 silenced).
August 07, 2019 - 08:45:19
Django version 2.2.4, using settings 'todo.settings'
Starting development server at http://127.0.0.1:7000/
Quit the server with CONTROL-C.
Watching for file changes with StatReloader
/home/abhinandan/PycharmProjects/todo/todo_list/views.py changed, reloading.
Performing system checks...

System check identified no issues (0 silenced).
August 07, 2019 - 08:45:23
Django version 2.2.4, using settings 'todo.settings'
Starting development server at http://127.0.0.1:7000/
Quit the server with CONTROL-C.
Watching for file changes with StatReloader
/home/abhinandan/PycharmProjects/todo/todo_list/views.py changed, reloading.
Performing system checks...

System check identified no issues (0 silenced).
August 07, 2019 - 08:45:32
Django version 2.2.4, using settings 'todo.settings'
Starting development server at http://127.0.0.1:7000/
Quit the server with CONTROL-C.
Watching for file changes with StatReloader
Exception in thread django-main-thread:
Traceback (most recent call last):
  File "/usr/lib/python3.5/threading.py", line 914, in _bootstrap_inner
    self.run()
  File "/usr/lib/python3.5/threading.py", line 862, in run
    self._target(*self._args, **self._kwargs)
  File "/home/abhinandan/PycharmProjects/todo/venv/lib/python3.5/site-packages/django/utils/autoreload.py", line 54, in wrapper
    fn(*args, **kwargs)
  File "/home/abhinandan/PycharmProjects/todo/venv/lib/python3.5/site-packages/django/core/management/commands/runserver.py", line 117, in inner_run
    self.check(display_num_errors=True)
  File "/home/abhinandan/PycharmProjects/todo/venv/lib/python3.5/site-packages/django/core/management/base.py", line 390, in check
    include_deployment_checks=include_deployment_checks,
  File "/home/abhinandan/PycharmProjects/todo/venv/lib/python3.5/site-packages/django/core/management/base.py", line 377, in _run_checks
    return checks.run_checks(**kwargs)
  File "/home/abhinandan/PycharmProjects/todo/venv/lib/python3.5/site-packages/django/core/checks/registry.py", line 72, in run_checks
    new_errors = check(app_configs=app_configs)
  File "/home/abhinandan/PycharmProjects/todo/venv/lib/python3.5/site-packages/django/core/checks/urls.py", line 40, in check_url_namespaces_unique
    all_namespaces = _load_all_namespaces(resolver)
  File "/home/abhinandan/PycharmProjects/todo/venv/lib/python3.5/site-packages/django/core/checks/urls.py", line 57, in _load_all_namespaces
    url_patterns = getattr(resolver, 'url_patterns', [])
  File "/home/abhinandan/PycharmProjects/todo/venv/lib/python3.5/site-packages/django/utils/functional.py", line 80, in __get__
    res = instance.__dict__[self.name] = self.func(instance)
  File "/home/abhinandan/PycharmProjects/todo/venv/lib/python3.5/site-packages/django/urls/resolvers.py", line 579, in url_patterns
    patterns = getattr(self.urlconf_module, "urlpatterns", self.urlconf_module)
  File "/home/abhinandan/PycharmProjects/todo/venv/lib/python3.5/site-packages/django/utils/functional.py", line 80, in __get__
    res = instance.__dict__[self.name] = self.func(instance)
  File "/home/abhinandan/PycharmProjects/todo/venv/lib/python3.5/site-packages/django/urls/resolvers.py", line 572, in urlconf_module
    return import_module(self.urlconf_name)
  File "/usr/lib/python3.5/importlib/__init__.py", line 126, in import_module
    return _bootstrap._gcd_import(name[level:], package, level)
  File "<frozen importlib._bootstrap>", line 986, in _gcd_import
  File "<frozen importlib._bootstrap>", line 969, in _find_and_load
  File "<frozen importlib._bootstrap>", line 958, in _find_and_load_unlocked
  File "<frozen importlib._bootstrap>", line 673, in _load_unlocked
  File "<frozen importlib._bootstrap_external>", line 665, in exec_module
  File "<frozen importlib._bootstrap>", line 222, in _call_with_frames_removed
  File "/home/abhinandan/PycharmProjects/todo/todo/urls.py", line 18, in <module>
    from todo_list import views
  File "/home/abhinandan/PycharmProjects/todo/todo_list/views.py", line 10
    if form
           ^
SyntaxError: invalid syntax

/home/abhinandan/PycharmProjects/todo/todo_list/views.py changed, reloading.
Performing system checks...

Watching for file changes with StatReloader
Exception in thread django-main-thread:
Traceback (most recent call last):
  File "/usr/lib/python3.5/threading.py", line 914, in _bootstrap_inner
    self.run()
  File "/usr/lib/python3.5/threading.py", line 862, in run
    self._target(*self._args, **self._kwargs)
  File "/home/abhinandan/PycharmProjects/todo/venv/lib/python3.5/site-packages/django/utils/autoreload.py", line 54, in wrapper
    fn(*args, **kwargs)
  File "/home/abhinandan/PycharmProjects/todo/venv/lib/python3.5/site-packages/django/core/management/commands/runserver.py", line 117, in inner_run
    self.check(display_num_errors=True)
  File "/home/abhinandan/PycharmProjects/todo/venv/lib/python3.5/site-packages/django/core/management/base.py", line 390, in check
    include_deployment_checks=include_deployment_checks,
  File "/home/abhinandan/PycharmProjects/todo/venv/lib/python3.5/site-packages/django/core/management/base.py", line 377, in _run_checks
    return checks.run_checks(**kwargs)
  File "/home/abhinandan/PycharmProjects/todo/venv/lib/python3.5/site-packages/django/core/checks/registry.py", line 72, in run_checks
    new_errors = check(app_configs=app_configs)
  File "/home/abhinandan/PycharmProjects/todo/venv/lib/python3.5/site-packages/django/core/checks/urls.py", line 40, in check_url_namespaces_unique
    all_namespaces = _load_all_namespaces(resolver)
  File "/home/abhinandan/PycharmProjects/todo/venv/lib/python3.5/site-packages/django/core/checks/urls.py", line 57, in _load_all_namespaces
    url_patterns = getattr(resolver, 'url_patterns', [])
  File "/home/abhinandan/PycharmProjects/todo/venv/lib/python3.5/site-packages/django/utils/functional.py", line 80, in __get__
    res = instance.__dict__[self.name] = self.func(instance)
  File "/home/abhinandan/PycharmProjects/todo/venv/lib/python3.5/site-packages/django/urls/resolvers.py", line 579, in url_patterns
    patterns = getattr(self.urlconf_module, "urlpatterns", self.urlconf_module)
  File "/home/abhinandan/PycharmProjects/todo/venv/lib/python3.5/site-packages/django/utils/functional.py", line 80, in __get__
    res = instance.__dict__[self.name] = self.func(instance)
  File "/home/abhinandan/PycharmProjects/todo/venv/lib/python3.5/site-packages/django/urls/resolvers.py", line 572, in urlconf_module
    return import_module(self.urlconf_name)
  File "/usr/lib/python3.5/importlib/__init__.py", line 126, in import_module
    return _bootstrap._gcd_import(name[level:], package, level)
  File "<frozen importlib._bootstrap>", line 986, in _gcd_import
  File "<frozen importlib._bootstrap>", line 969, in _find_and_load
  File "<frozen importlib._bootstrap>", line 958, in _find_and_load_unlocked
  File "<frozen importlib._bootstrap>", line 673, in _load_unlocked
  File "<frozen importlib._bootstrap_external>", line 665, in exec_module
  File "<frozen importlib._bootstrap>", line 222, in _call_with_frames_removed
  File "/home/abhinandan/PycharmProjects/todo/todo/urls.py", line 18, in <module>
    from todo_list import views
  File "/home/abhinandan/PycharmProjects/todo/todo_list/views.py", line 12
    return render(request,"home.html",{})
    ^
IndentationError: expected an indented block

/home/abhinandan/PycharmProjects/todo/todo_list/views.py changed, reloading.
Performing system checks...

Watching for file changes with StatReloader
Exception in thread django-main-thread:
Traceback (most recent call last):
  File "/usr/lib/python3.5/threading.py", line 914, in _bootstrap_inner
    self.run()
  File "/usr/lib/python3.5/threading.py", line 862, in run
    self._target(*self._args, **self._kwargs)
  File "/home/abhinandan/PycharmProjects/todo/venv/lib/python3.5/site-packages/django/utils/autoreload.py", line 54, in wrapper
    fn(*args, **kwargs)
  File "/home/abhinandan/PycharmProjects/todo/venv/lib/python3.5/site-packages/django/core/management/commands/runserver.py", line 117, in inner_run
    self.check(display_num_errors=True)
  File "/home/abhinandan/PycharmProjects/todo/venv/lib/python3.5/site-packages/django/core/management/base.py", line 390, in check
    include_deployment_checks=include_deployment_checks,
  File "/home/abhinandan/PycharmProjects/todo/venv/lib/python3.5/site-packages/django/core/management/base.py", line 377, in _run_checks
    return checks.run_checks(**kwargs)
  File "/home/abhinandan/PycharmProjects/todo/venv/lib/python3.5/site-packages/django/core/checks/registry.py", line 72, in run_checks
    new_errors = check(app_configs=app_configs)
  File "/home/abhinandan/PycharmProjects/todo/venv/lib/python3.5/site-packages/django/core/checks/urls.py", line 40, in check_url_namespaces_unique
    all_namespaces = _load_all_namespaces(resolver)
  File "/home/abhinandan/PycharmProjects/todo/venv/lib/python3.5/site-packages/django/core/checks/urls.py", line 57, in _load_all_namespaces
    url_patterns = getattr(resolver, 'url_patterns', [])
  File "/home/abhinandan/PycharmProjects/todo/venv/lib/python3.5/site-packages/django/utils/functional.py", line 80, in __get__
    res = instance.__dict__[self.name] = self.func(instance)
  File "/home/abhinandan/PycharmProjects/todo/venv/lib/python3.5/site-packages/django/urls/resolvers.py", line 579, in url_patterns
    patterns = getattr(self.urlconf_module, "urlpatterns", self.urlconf_module)
  File "/home/abhinandan/PycharmProjects/todo/venv/lib/python3.5/site-packages/django/utils/functional.py", line 80, in __get__
    res = instance.__dict__[self.name] = self.func(instance)
  File "/home/abhinandan/PycharmProjects/todo/venv/lib/python3.5/site-packages/django/urls/resolvers.py", line 572, in urlconf_module
    return import_module(self.urlconf_name)
  File "/usr/lib/python3.5/importlib/__init__.py", line 126, in import_module
    return _bootstrap._gcd_import(name[level:], package, level)
  File "<frozen importlib._bootstrap>", line 986, in _gcd_import
  File "<frozen importlib._bootstrap>", line 969, in _find_and_load
  File "<frozen importlib._bootstrap>", line 958, in _find_and_load_unlocked
  File "<frozen importlib._bootstrap>", line 673, in _load_unlocked
  File "<frozen importlib._bootstrap_external>", line 665, in exec_module
  File "<frozen importlib._bootstrap>", line 222, in _call_with_frames_removed
  File "/home/abhinandan/PycharmProjects/todo/todo/urls.py", line 18, in <module>
    from todo_list import views
  File "/home/abhinandan/PycharmProjects/todo/todo_list/views.py", line 11
    from.save()
             ^
SyntaxError: invalid syntax

/home/abhinandan/PycharmProjects/todo/todo_list/views.py changed, reloading.
Performing system checks...

Watching for file changes with StatReloader
/home/abhinandan/PycharmProjects/todo/todo_list/views.py changed, reloading.
Performing system checks...

System check identified no issues (0 silenced).
August 07, 2019 - 08:46:23
Django version 2.2.4, using settings 'todo.settings'
Starting development server at http://127.0.0.1:7000/
Quit the server with CONTROL-C.
Watching for file changes with StatReloader
Exception in thread django-main-thread:
Traceback (most recent call last):
  File "/usr/lib/python3.5/threading.py", line 914, in _bootstrap_inner
    self.run()
  File "/usr/lib/python3.5/threading.py", line 862, in run
    self._target(*self._args, **self._kwargs)
  File "/home/abhinandan/PycharmProjects/todo/venv/lib/python3.5/site-packages/django/utils/autoreload.py", line 54, in wrapper
    fn(*args, **kwargs)
  File "/home/abhinandan/PycharmProjects/todo/venv/lib/python3.5/site-packages/django/core/management/commands/runserver.py", line 117, in inner_run
    self.check(display_num_errors=True)
  File "/home/abhinandan/PycharmProjects/todo/venv/lib/python3.5/site-packages/django/core/management/base.py", line 390, in check
    include_deployment_checks=include_deployment_checks,
  File "/home/abhinandan/PycharmProjects/todo/venv/lib/python3.5/site-packages/django/core/management/base.py", line 377, in _run_checks
    return checks.run_checks(**kwargs)
  File "/home/abhinandan/PycharmProjects/todo/venv/lib/python3.5/site-packages/django/core/checks/registry.py", line 72, in run_checks
    new_errors = check(app_configs=app_configs)
  File "/home/abhinandan/PycharmProjects/todo/venv/lib/python3.5/site-packages/django/core/checks/urls.py", line 40, in check_url_namespaces_unique
    all_namespaces = _load_all_namespaces(resolver)
  File "/home/abhinandan/PycharmProjects/todo/venv/lib/python3.5/site-packages/django/core/checks/urls.py", line 57, in _load_all_namespaces
    url_patterns = getattr(resolver, 'url_patterns', [])
  File "/home/abhinandan/PycharmProjects/todo/venv/lib/python3.5/site-packages/django/utils/functional.py", line 80, in __get__
    res = instance.__dict__[self.name] = self.func(instance)
  File "/home/abhinandan/PycharmProjects/todo/venv/lib/python3.5/site-packages/django/urls/resolvers.py", line 579, in url_patterns
    patterns = getattr(self.urlconf_module, "urlpatterns", self.urlconf_module)
  File "/home/abhinandan/PycharmProjects/todo/venv/lib/python3.5/site-packages/django/utils/functional.py", line 80, in __get__
    res = instance.__dict__[self.name] = self.func(instance)
  File "/home/abhinandan/PycharmProjects/todo/venv/lib/python3.5/site-packages/django/urls/resolvers.py", line 572, in urlconf_module
    return import_module(self.urlconf_name)
  File "/usr/lib/python3.5/importlib/__init__.py", line 126, in import_module
    return _bootstrap._gcd_import(name[level:], package, level)
  File "<frozen importlib._bootstrap>", line 986, in _gcd_import
  File "<frozen importlib._bootstrap>", line 969, in _find_and_load
  File "<frozen importlib._bootstrap>", line 958, in _find_and_load_unlocked
  File "<frozen importlib._bootstrap>", line 673, in _load_unlocked
  File "<frozen importlib._bootstrap_external>", line 665, in exec_module
  File "<frozen importlib._bootstrap>", line 222, in _call_with_frames_removed
  File "/home/abhinandan/PycharmProjects/todo/todo/urls.py", line 18, in <module>
    from todo_list import views
  File "/home/abhinandan/PycharmProjects/todo/todo_list/views.py", line 12
    all_items =
              ^
SyntaxError: invalid syntax

/home/abhinandan/PycharmProjects/todo/todo_list/views.py changed, reloading.
Performing system checks...

Watching for file changes with StatReloader
/home/abhinandan/PycharmProjects/todo/todo_list/views.py changed, reloading.
Performing system checks...

System check identified no issues (0 silenced).
August 07, 2019 - 08:46:45
Django version 2.2.4, using settings 'todo.settings'
Starting development server at http://127.0.0.1:7000/
Quit the server with CONTROL-C.
Watching for file changes with StatReloader
/home/abhinandan/PycharmProjects/todo/todo_list/views.py changed, reloading.
Performing system checks...

System check identified no issues (0 silenced).
August 07, 2019 - 08:46:52
Django version 2.2.4, using settings 'todo.settings'
Starting development server at http://127.0.0.1:7000/
Quit the server with CONTROL-C.
Watching for file changes with StatReloader
/home/abhinandan/PycharmProjects/todo/todo_list/views.py changed, reloading.
Performing system checks...

System check identified no issues (0 silenced).
August 07, 2019 - 08:46:58
Django version 2.2.4, using settings 'todo.settings'
Starting development server at http://127.0.0.1:7000/
Quit the server with CONTROL-C.
Watching for file changes with StatReloader
/home/abhinandan/PycharmProjects/todo/todo_list/views.py changed, reloading.
Performing system checks...

System check identified no issues (0 silenced).
August 07, 2019 - 08:47:10
Django version 2.2.4, using settings 'todo.settings'
Starting development server at http://127.0.0.1:7000/
Quit the server with CONTROL-C.
Watching for file changes with StatReloader
/home/abhinandan/PycharmProjects/todo/todo_list/views.py changed, reloading.
Performing system checks...

System check identified no issues (0 silenced).
August 07, 2019 - 08:47:24
Django version 2.2.4, using settings 'todo.settings'
Starting development server at http://127.0.0.1:7000/
Quit the server with CONTROL-C.
Watching for file changes with StatReloader
/home/abhinandan/PycharmProjects/todo/todo_list/views.py changed, reloading.
Performing system checks...

System check identified no issues (0 silenced).
August 07, 2019 - 08:47:33
Django version 2.2.4, using settings 'todo.settings'
Starting development server at http://127.0.0.1:7000/
Quit the server with CONTROL-C.
Watching for file changes with StatReloader
/home/abhinandan/PycharmProjects/todo/todo_list/views.py changed, reloading.
Performing system checks...

System check identified no issues (0 silenced).
August 07, 2019 - 08:47:38
Django version 2.2.4, using settings 'todo.settings'
Starting development server at http://127.0.0.1:7000/
Quit the server with CONTROL-C.
Watching for file changes with StatReloader
/home/abhinandan/PycharmProjects/todo/todo_list/views.py changed, reloading.
Performing system checks...

System check identified no issues (0 silenced).
August 07, 2019 - 08:47:52
Django version 2.2.4, using settings 'todo.settings'
Starting development server at http://127.0.0.1:7000/
Quit the server with CONTROL-C.
Watching for file changes with StatReloader
/home/abhinandan/PycharmProjects/todo/todo_list/views.py changed, reloading.
Performing system checks...

System check identified no issues (0 silenced).
August 07, 2019 - 08:48:15
Django version 2.2.4, using settings 'todo.settings'
Starting development server at http://127.0.0.1:7000/
Quit the server with CONTROL-C.
Watching for file changes with StatReloader
/home/abhinandan/PycharmProjects/todo/todo_list/views.py changed, reloading.
Performing system checks...

System check identified no issues (0 silenced).
August 07, 2019 - 08:48:22
Django version 2.2.4, using settings 'todo.settings'
Starting development server at http://127.0.0.1:7000/
Quit the server with CONTROL-C.
Watching for file changes with StatReloader
Exception in thread django-main-thread:
Traceback (most recent call last):
  File "/usr/lib/python3.5/threading.py", line 914, in _bootstrap_inner
    self.run()
  File "/usr/lib/python3.5/threading.py", line 862, in run
    self._target(*self._args, **self._kwargs)
  File "/home/abhinandan/PycharmProjects/todo/venv/lib/python3.5/site-packages/django/utils/autoreload.py", line 54, in wrapper
    fn(*args, **kwargs)
  File "/home/abhinandan/PycharmProjects/todo/venv/lib/python3.5/site-packages/django/core/management/commands/runserver.py", line 117, in inner_run
    self.check(display_num_errors=True)
  File "/home/abhinandan/PycharmProjects/todo/venv/lib/python3.5/site-packages/django/core/management/base.py", line 390, in check
    include_deployment_checks=include_deployment_checks,
  File "/home/abhinandan/PycharmProjects/todo/venv/lib/python3.5/site-packages/django/core/management/base.py", line 377, in _run_checks
    return checks.run_checks(**kwargs)
  File "/home/abhinandan/PycharmProjects/todo/venv/lib/python3.5/site-packages/django/core/checks/registry.py", line 72, in run_checks
    new_errors = check(app_configs=app_configs)
  File "/home/abhinandan/PycharmProjects/todo/venv/lib/python3.5/site-packages/django/core/checks/urls.py", line 40, in check_url_namespaces_unique
    all_namespaces = _load_all_namespaces(resolver)
  File "/home/abhinandan/PycharmProjects/todo/venv/lib/python3.5/site-packages/django/core/checks/urls.py", line 57, in _load_all_namespaces
    url_patterns = getattr(resolver, 'url_patterns', [])
  File "/home/abhinandan/PycharmProjects/todo/venv/lib/python3.5/site-packages/django/utils/functional.py", line 80, in __get__
    res = instance.__dict__[self.name] = self.func(instance)
  File "/home/abhinandan/PycharmProjects/todo/venv/lib/python3.5/site-packages/django/urls/resolvers.py", line 579, in url_patterns
    patterns = getattr(self.urlconf_module, "urlpatterns", self.urlconf_module)
  File "/home/abhinandan/PycharmProjects/todo/venv/lib/python3.5/site-packages/django/utils/functional.py", line 80, in __get__
    res = instance.__dict__[self.name] = self.func(instance)
  File "/home/abhinandan/PycharmProjects/todo/venv/lib/python3.5/site-packages/django/urls/resolvers.py", line 572, in urlconf_module
    return import_module(self.urlconf_name)
  File "/usr/lib/python3.5/importlib/__init__.py", line 126, in import_module
    return _bootstrap._gcd_import(name[level:], package, level)
  File "<frozen importlib._bootstrap>", line 986, in _gcd_import
  File "<frozen importlib._bootstrap>", line 969, in _find_and_load
  File "<frozen importlib._bootstrap>", line 958, in _find_and_load_unlocked
  File "<frozen importlib._bootstrap>", line 673, in _load_unlocked
  File "<frozen importlib._bootstrap_external>", line 665, in exec_module
  File "<frozen importlib._bootstrap>", line 222, in _call_with_frames_removed
  File "/home/abhinandan/PycharmProjects/todo/todo/urls.py", line 18, in <module>
    from todo_list import views
  File "/home/abhinandan/PycharmProjects/todo/todo_list/views.py", line 16
    
    ^
SyntaxError: unexpected EOF while parsing

/home/abhinandan/PycharmProjects/todo/todo_list/views.py changed, reloading.
Performing system checks...

Watching for file changes with StatReloader
/home/abhinandan/PycharmProjects/todo/todo_list/views.py changed, reloading.
Performing system checks...

System check identified no issues (0 silenced).
August 07, 2019 - 08:48:47
Django version 2.2.4, using settings 'todo.settings'
Starting development server at http://127.0.0.1:7000/
Quit the server with CONTROL-C.
Watching for file changes with StatReloader
[07/Aug/2019 08:58:01] "GET / HTTP/1.1" 200 2258
Forbidden (CSRF token missing or incorrect.): /
[07/Aug/2019 08:59:27] "POST / HTTP/1.1" 403 2513
Forbidden (CSRF token missing or incorrect.): /
[07/Aug/2019 09:00:06] "POST / HTTP/1.1" 403 2513
Forbidden (CSRF token missing or incorrect.): /
[07/Aug/2019 09:00:41] "POST / HTTP/1.1" 403 2513
Forbidden (CSRF token missing or incorrect.): /
[07/Aug/2019 09:01:08] "POST / HTTP/1.1" 403 2513
Forbidden (CSRF token missing or incorrect.): /
[07/Aug/2019 09:01:19] "POST / HTTP/1.1" 403 2513
Forbidden (CSRF token missing or incorrect.): /
[07/Aug/2019 09:02:22] "POST / HTTP/1.1" 403 2513
Forbidden (CSRF token missing or incorrect.): /
[07/Aug/2019 09:04:43] "POST / HTTP/1.1" 403 2513
Forbidden (CSRF token missing or incorrect.): /
[07/Aug/2019 09:04:47] "POST / HTTP/1.1" 403 2513
[07/Aug/2019 09:05:03] "GET / HTTP/1.1" 200 2381
Not Found: /home.html
[07/Aug/2019 09:05:08] "POST /home.html HTTP/1.1" 404 2125
Not Found: /home.html
[07/Aug/2019 09:06:46] "POST /home.html HTTP/1.1" 404 2125
Not Found: /home.html
[07/Aug/2019 09:06:51] "POST /home.html HTTP/1.1" 404 2125
[07/Aug/2019 09:06:58] "GET / HTTP/1.1" 200 2373
[07/Aug/2019 09:07:00] "GET / HTTP/1.1" 200 2373
[07/Aug/2019 09:07:03] "POST / HTTP/1.1" 200 2925
[07/Aug/2019 09:07:37] "POST / HTTP/1.1" 200 2997
[07/Aug/2019 09:10:51] "POST / HTTP/1.1" 200 3473
[07/Aug/2019 09:11:05] "GET / HTTP/1.1" 200 3046
[07/Aug/2019 09:11:08] "GET / HTTP/1.1" 200 3046
[07/Aug/2019 09:12:34] "GET / HTTP/1.1" 200 3280
/home/abhinandan/PycharmProjects/todo/todo_list/views.py changed, reloading.
Performing system checks...

System check identified no issues (0 silenced).
August 07, 2019 - 08:48:58
Django version 2.2.4, using settings 'todo.settings'
Starting development server at http://127.0.0.1:7000/
Quit the server with CONTROL-C.
Watching for file changes with StatReloader
Exception in thread django-main-thread:
Traceback (most recent call last):
  File "/usr/lib/python3.5/threading.py", line 914, in _bootstrap_inner
    self.run()
  File "/usr/lib/python3.5/threading.py", line 862, in run
    self._target(*self._args, **self._kwargs)
  File "/home/abhinandan/PycharmProjects/todo/venv/lib/python3.5/site-packages/django/utils/autoreload.py", line 54, in wrapper
    fn(*args, **kwargs)
  File "/home/abhinandan/PycharmProjects/todo/venv/lib/python3.5/site-packages/django/core/management/commands/runserver.py", line 117, in inner_run
    self.check(display_num_errors=True)
  File "/home/abhinandan/PycharmProjects/todo/venv/lib/python3.5/site-packages/django/core/management/base.py", line 390, in check
    include_deployment_checks=include_deployment_checks,
  File "/home/abhinandan/PycharmProjects/todo/venv/lib/python3.5/site-packages/django/core/management/base.py", line 377, in _run_checks
    return checks.run_checks(**kwargs)
  File "/home/abhinandan/PycharmProjects/todo/venv/lib/python3.5/site-packages/django/core/checks/registry.py", line 72, in run_checks
    new_errors = check(app_configs=app_configs)
  File "/home/abhinandan/PycharmProjects/todo/venv/lib/python3.5/site-packages/django/core/checks/urls.py", line 40, in check_url_namespaces_unique
    all_namespaces = _load_all_namespaces(resolver)
  File "/home/abhinandan/PycharmProjects/todo/venv/lib/python3.5/site-packages/django/core/checks/urls.py", line 57, in _load_all_namespaces
    url_patterns = getattr(resolver, 'url_patterns', [])
  File "/home/abhinandan/PycharmProjects/todo/venv/lib/python3.5/site-packages/django/utils/functional.py", line 80, in __get__
    res = instance.__dict__[self.name] = self.func(instance)
  File "/home/abhinandan/PycharmProjects/todo/venv/lib/python3.5/site-packages/django/urls/resolvers.py", line 579, in url_patterns
    patterns = getattr(self.urlconf_module, "urlpatterns", self.urlconf_module)
  File "/home/abhinandan/PycharmProjects/todo/venv/lib/python3.5/site-packages/django/utils/functional.py", line 80, in __get__
    res = instance.__dict__[self.name] = self.func(instance)
  File "/home/abhinandan/PycharmProjects/todo/venv/lib/python3.5/site-packages/django/urls/resolvers.py", line 572, in urlconf_module
    return import_module(self.urlconf_name)
  File "/usr/lib/python3.5/importlib/__init__.py", line 126, in import_module
    return _bootstrap._gcd_import(name[level:], package, level)
  File "<frozen importlib._bootstrap>", line 986, in _gcd_import
  File "<frozen importlib._bootstrap>", line 969, in _find_and_load
  File "<frozen importlib._bootstrap>", line 958, in _find_and_load_unlocked
  File "<frozen importlib._bootstrap>", line 673, in _load_unlocked
  File "<frozen importlib._bootstrap_external>", line 665, in exec_module
  File "<frozen importlib._bootstrap>", line 222, in _call_with_frames_removed
  File "/home/abhinandan/PycharmProjects/todo/todo/urls.py", line 18, in <module>
    from todo_list import views
  File "/home/abhinandan/PycharmProjects/todo/todo_list/views.py", line 19
    def delete()
               ^
SyntaxError: invalid syntax

/home/abhinandan/PycharmProjects/todo/todo_list/views.py changed, reloading.
Performing system checks...

Watching for file changes with StatReloader
/home/abhinandan/PycharmProjects/todo/todo_list/urls.py changed, reloading.
Performing system checks...

System check identified no issues (0 silenced).
August 07, 2019 - 09:13:17
Django version 2.2.4, using settings 'todo.settings'
Starting development server at http://127.0.0.1:7000/
Quit the server with CONTROL-C.
Watching for file changes with StatReloader
Exception in thread django-main-thread:
Traceback (most recent call last):
  File "/usr/lib/python3.5/threading.py", line 914, in _bootstrap_inner
    self.run()
  File "/usr/lib/python3.5/threading.py", line 862, in run
    self._target(*self._args, **self._kwargs)
  File "/home/abhinandan/PycharmProjects/todo/venv/lib/python3.5/site-packages/django/utils/autoreload.py", line 54, in wrapper
    fn(*args, **kwargs)
  File "/home/abhinandan/PycharmProjects/todo/venv/lib/python3.5/site-packages/django/core/management/commands/runserver.py", line 117, in inner_run
    self.check(display_num_errors=True)
  File "/home/abhinandan/PycharmProjects/todo/venv/lib/python3.5/site-packages/django/core/management/base.py", line 390, in check
    include_deployment_checks=include_deployment_checks,
  File "/home/abhinandan/PycharmProjects/todo/venv/lib/python3.5/site-packages/django/core/management/base.py", line 377, in _run_checks
    return checks.run_checks(**kwargs)
  File "/home/abhinandan/PycharmProjects/todo/venv/lib/python3.5/site-packages/django/core/checks/registry.py", line 72, in run_checks
    new_errors = check(app_configs=app_configs)
  File "/home/abhinandan/PycharmProjects/todo/venv/lib/python3.5/site-packages/django/core/checks/urls.py", line 13, in check_url_config
    return check_resolver(resolver)
  File "/home/abhinandan/PycharmProjects/todo/venv/lib/python3.5/site-packages/django/core/checks/urls.py", line 23, in check_resolver
    return check_method()
  File "/home/abhinandan/PycharmProjects/todo/venv/lib/python3.5/site-packages/django/urls/resolvers.py", line 398, in check
    for pattern in self.url_patterns:
  File "/home/abhinandan/PycharmProjects/todo/venv/lib/python3.5/site-packages/django/utils/functional.py", line 80, in __get__
    res = instance.__dict__[self.name] = self.func(instance)
  File "/home/abhinandan/PycharmProjects/todo/venv/lib/python3.5/site-packages/django/urls/resolvers.py", line 579, in url_patterns
    patterns = getattr(self.urlconf_module, "urlpatterns", self.urlconf_module)
  File "/home/abhinandan/PycharmProjects/todo/venv/lib/python3.5/site-packages/django/utils/functional.py", line 80, in __get__
    res = instance.__dict__[self.name] = self.func(instance)
  File "/home/abhinandan/PycharmProjects/todo/venv/lib/python3.5/site-packages/django/urls/resolvers.py", line 572, in urlconf_module
    return import_module(self.urlconf_name)
  File "/usr/lib/python3.5/importlib/__init__.py", line 126, in import_module
    return _bootstrap._gcd_import(name[level:], package, level)
  File "<frozen importlib._bootstrap>", line 986, in _gcd_import
  File "<frozen importlib._bootstrap>", line 969, in _find_and_load
  File "<frozen importlib._bootstrap>", line 958, in _find_and_load_unlocked
  File "<frozen importlib._bootstrap>", line 673, in _load_unlocked
  File "<frozen importlib._bootstrap_external>", line 665, in exec_module
  File "<frozen importlib._bootstrap>", line 222, in _call_with_frames_removed
  File "/home/abhinandan/PycharmProjects/todo/todo/urls.py", line 22, in <module>
    path('', include('todo_list.urls')),
  File "/home/abhinandan/PycharmProjects/todo/venv/lib/python3.5/site-packages/django/urls/conf.py", line 34, in include
    urlconf_module = import_module(urlconf_module)
  File "/usr/lib/python3.5/importlib/__init__.py", line 126, in import_module
    return _bootstrap._gcd_import(name[level:], package, level)
  File "<frozen importlib._bootstrap>", line 986, in _gcd_import
  File "<frozen importlib._bootstrap>", line 969, in _find_and_load
  File "<frozen importlib._bootstrap>", line 958, in _find_and_load_unlocked
  File "<frozen importlib._bootstrap>", line 673, in _load_unlocked
  File "<frozen importlib._bootstrap_external>", line 665, in exec_module
  File "<frozen importlib._bootstrap>", line 222, in _call_with_frames_removed
  File "/home/abhinandan/PycharmProjects/todo/todo_list/urls.py", line 6, in <module>
    path('delete<list_id>/',views.delete, name="delete"),
AttributeError: module 'todo_list.views' has no attribute 'delete'

/home/abhinandan/PycharmProjects/todo/todo_list/views.py changed, reloading.
Performing system checks...

Watching for file changes with StatReloader
/home/abhinandan/PycharmProjects/todo/todo_list/views.py changed, reloading.
Performing system checks...

System check identified no issues (0 silenced).
August 07, 2019 - 09:14:55
Django version 2.2.4, using settings 'todo.settings'
Starting development server at http://127.0.0.1:7000/
Quit the server with CONTROL-C.
Watching for file changes with StatReloader
/home/abhinandan/PycharmProjects/todo/todo_list/views.py changed, reloading.
Performing system checks...

System check identified no issues (0 silenced).
August 07, 2019 - 09:15:11
Django version 2.2.4, using settings 'todo.settings'
Starting development server at http://127.0.0.1:7000/
Quit the server with CONTROL-C.
Watching for file changes with StatReloader
Exception in thread django-main-thread:
Traceback (most recent call last):
  File "/usr/lib/python3.5/threading.py", line 914, in _bootstrap_inner
    self.run()
  File "/usr/lib/python3.5/threading.py", line 862, in run
    self._target(*self._args, **self._kwargs)
  File "/home/abhinandan/PycharmProjects/todo/venv/lib/python3.5/site-packages/django/utils/autoreload.py", line 54, in wrapper
    fn(*args, **kwargs)
  File "/home/abhinandan/PycharmProjects/todo/venv/lib/python3.5/site-packages/django/core/management/commands/runserver.py", line 117, in inner_run
    self.check(display_num_errors=True)
  File "/home/abhinandan/PycharmProjects/todo/venv/lib/python3.5/site-packages/django/core/management/base.py", line 390, in check
    include_deployment_checks=include_deployment_checks,
  File "/home/abhinandan/PycharmProjects/todo/venv/lib/python3.5/site-packages/django/core/management/base.py", line 377, in _run_checks
    return checks.run_checks(**kwargs)
  File "/home/abhinandan/PycharmProjects/todo/venv/lib/python3.5/site-packages/django/core/checks/registry.py", line 72, in run_checks
    new_errors = check(app_configs=app_configs)
  File "/home/abhinandan/PycharmProjects/todo/venv/lib/python3.5/site-packages/django/core/checks/urls.py", line 40, in check_url_namespaces_unique
    all_namespaces = _load_all_namespaces(resolver)
  File "/home/abhinandan/PycharmProjects/todo/venv/lib/python3.5/site-packages/django/core/checks/urls.py", line 57, in _load_all_namespaces
    url_patterns = getattr(resolver, 'url_patterns', [])
  File "/home/abhinandan/PycharmProjects/todo/venv/lib/python3.5/site-packages/django/utils/functional.py", line 80, in __get__
    res = instance.__dict__[self.name] = self.func(instance)
  File "/home/abhinandan/PycharmProjects/todo/venv/lib/python3.5/site-packages/django/urls/resolvers.py", line 579, in url_patterns
    patterns = getattr(self.urlconf_module, "urlpatterns", self.urlconf_module)
  File "/home/abhinandan/PycharmProjects/todo/venv/lib/python3.5/site-packages/django/utils/functional.py", line 80, in __get__
    res = instance.__dict__[self.name] = self.func(instance)
  File "/home/abhinandan/PycharmProjects/todo/venv/lib/python3.5/site-packages/django/urls/resolvers.py", line 572, in urlconf_module
    return import_module(self.urlconf_name)
  File "/usr/lib/python3.5/importlib/__init__.py", line 126, in import_module
    return _bootstrap._gcd_import(name[level:], package, level)
  File "<frozen importlib._bootstrap>", line 986, in _gcd_import
  File "<frozen importlib._bootstrap>", line 969, in _find_and_load
  File "<frozen importlib._bootstrap>", line 958, in _find_and_load_unlocked
  File "<frozen importlib._bootstrap>", line 673, in _load_unlocked
  File "<frozen importlib._bootstrap_external>", line 665, in exec_module
  File "<frozen importlib._bootstrap>", line 222, in _call_with_frames_removed
  File "/home/abhinandan/PycharmProjects/todo/todo/urls.py", line 18, in <module>
    from todo_list import views
  File "/home/abhinandan/PycharmProjects/todo/todo_list/views.py", line 21
    item = List.objects.
                       ^
SyntaxError: invalid syntax

/home/abhinandan/PycharmProjects/todo/todo_list/views.py changed, reloading.
Performing system checks...

Watching for file changes with StatReloader
/home/abhinandan/PycharmProjects/todo/todo_list/views.py changed, reloading.
Performing system checks...

System check identified no issues (0 silenced).
August 07, 2019 - 09:15:35
Django version 2.2.4, using settings 'todo.settings'
Starting development server at http://127.0.0.1:7000/
Quit the server with CONTROL-C.
Watching for file changes with StatReloader
/home/abhinandan/PycharmProjects/todo/todo_list/views.py changed, reloading.
Performing system checks...

System check identified no issues (0 silenced).
August 07, 2019 - 09:15:42
Django version 2.2.4, using settings 'todo.settings'
Starting development server at http://127.0.0.1:7000/
Quit the server with CONTROL-C.
Watching for file changes with StatReloader
/home/abhinandan/PycharmProjects/todo/todo_list/views.py changed, reloading.
Performing system checks...

System check identified no issues (0 silenced).
August 07, 2019 - 09:15:54
Django version 2.2.4, using settings 'todo.settings'
Starting development server at http://127.0.0.1:7000/
Quit the server with CONTROL-C.
Watching for file changes with StatReloader
/home/abhinandan/PycharmProjects/todo/todo_list/views.py changed, reloading.
Performing system checks...

System check identified no issues (0 silenced).
August 07, 2019 - 09:16:10
Django version 2.2.4, using settings 'todo.settings'
Starting development server at http://127.0.0.1:7000/
Quit the server with CONTROL-C.
Watching for file changes with StatReloader
/home/abhinandan/PycharmProjects/todo/todo_list/views.py changed, reloading.
Performing system checks...

System check identified no issues (0 silenced).
August 07, 2019 - 09:16:19
Django version 2.2.4, using settings 'todo.settings'
Starting development server at http://127.0.0.1:7000/
Quit the server with CONTROL-C.
Watching for file changes with StatReloader
[07/Aug/2019 09:18:50] "GET / HTTP/1.1" 200 3352
[07/Aug/2019 09:18:53] "GET /delete/3 HTTP/1.1" 302 0
[07/Aug/2019 09:18:53] "GET / HTTP/1.1" 200 3486
[07/Aug/2019 09:18:57] "GET / HTTP/1.1" 200 3066
/home/abhinandan/PycharmProjects/todo/todo_list/urls.py changed, reloading.
Performing system checks...

System check identified no issues (0 silenced).
August 07, 2019 - 09:16:24
Django version 2.2.4, using settings 'todo.settings'
Starting development server at http://127.0.0.1:7000/
Quit the server with CONTROL-C.
Watching for file changes with StatReloader
Exception in thread django-main-thread:
Traceback (most recent call last):
  File "/usr/lib/python3.5/threading.py", line 914, in _bootstrap_inner
    self.run()
  File "/usr/lib/python3.5/threading.py", line 862, in run
    self._target(*self._args, **self._kwargs)
  File "/home/abhinandan/PycharmProjects/todo/venv/lib/python3.5/site-packages/django/utils/autoreload.py", line 54, in wrapper
    fn(*args, **kwargs)
  File "/home/abhinandan/PycharmProjects/todo/venv/lib/python3.5/site-packages/django/core/management/commands/runserver.py", line 117, in inner_run
    self.check(display_num_errors=True)
  File "/home/abhinandan/PycharmProjects/todo/venv/lib/python3.5/site-packages/django/core/management/base.py", line 390, in check
    include_deployment_checks=include_deployment_checks,
  File "/home/abhinandan/PycharmProjects/todo/venv/lib/python3.5/site-packages/django/core/management/base.py", line 377, in _run_checks
    return checks.run_checks(**kwargs)
  File "/home/abhinandan/PycharmProjects/todo/venv/lib/python3.5/site-packages/django/core/checks/registry.py", line 72, in run_checks
    new_errors = check(app_configs=app_configs)
  File "/home/abhinandan/PycharmProjects/todo/venv/lib/python3.5/site-packages/django/core/checks/urls.py", line 13, in check_url_config
    return check_resolver(resolver)
  File "/home/abhinandan/PycharmProjects/todo/venv/lib/python3.5/site-packages/django/core/checks/urls.py", line 23, in check_resolver
    return check_method()
  File "/home/abhinandan/PycharmProjects/todo/venv/lib/python3.5/site-packages/django/urls/resolvers.py", line 398, in check
    for pattern in self.url_patterns:
  File "/home/abhinandan/PycharmProjects/todo/venv/lib/python3.5/site-packages/django/utils/functional.py", line 80, in __get__
    res = instance.__dict__[self.name] = self.func(instance)
  File "/home/abhinandan/PycharmProjects/todo/venv/lib/python3.5/site-packages/django/urls/resolvers.py", line 579, in url_patterns
    patterns = getattr(self.urlconf_module, "urlpatterns", self.urlconf_module)
  File "/home/abhinandan/PycharmProjects/todo/venv/lib/python3.5/site-packages/django/utils/functional.py", line 80, in __get__
    res = instance.__dict__[self.name] = self.func(instance)
  File "/home/abhinandan/PycharmProjects/todo/venv/lib/python3.5/site-packages/django/urls/resolvers.py", line 572, in urlconf_module
    return import_module(self.urlconf_name)
  File "/usr/lib/python3.5/importlib/__init__.py", line 126, in import_module
    return _bootstrap._gcd_import(name[level:], package, level)
  File "<frozen importlib._bootstrap>", line 986, in _gcd_import
  File "<frozen importlib._bootstrap>", line 969, in _find_and_load
  File "<frozen importlib._bootstrap>", line 958, in _find_and_load_unlocked
  File "<frozen importlib._bootstrap>", line 673, in _load_unlocked
  File "<frozen importlib._bootstrap_external>", line 665, in exec_module
  File "<frozen importlib._bootstrap>", line 222, in _call_with_frames_removed
  File "/home/abhinandan/PycharmProjects/todo/todo/urls.py", line 22, in <module>
    path('', include('todo_list.urls')),
  File "/home/abhinandan/PycharmProjects/todo/venv/lib/python3.5/site-packages/django/urls/conf.py", line 34, in include
    urlconf_module = import_module(urlconf_module)
  File "/usr/lib/python3.5/importlib/__init__.py", line 126, in import_module
    return _bootstrap._gcd_import(name[level:], package, level)
  File "<frozen importlib._bootstrap>", line 986, in _gcd_import
  File "<frozen importlib._bootstrap>", line 969, in _find_and_load
  File "<frozen importlib._bootstrap>", line 958, in _find_and_load_unlocked
  File "<frozen importlib._bootstrap>", line 673, in _load_unlocked
  File "<frozen importlib._bootstrap_external>", line 665, in exec_module
  File "<frozen importlib._bootstrap>", line 222, in _call_with_frames_removed
  File "/home/abhinandan/PycharmProjects/todo/todo_list/urls.py", line 7, in <module>
    path('cross_off/<list_id>',views.cross_off, name="crossoff"),
AttributeError: module 'todo_list.views' has no attribute 'cross_off'

/home/abhinandan/PycharmProjects/todo/todo_list/urls.py changed, reloading.
Performing system checks...

Watching for file changes with StatReloader
Exception in thread django-main-thread:
Traceback (most recent call last):
  File "/usr/lib/python3.5/threading.py", line 914, in _bootstrap_inner
    self.run()
  File "/usr/lib/python3.5/threading.py", line 862, in run
    self._target(*self._args, **self._kwargs)
  File "/home/abhinandan/PycharmProjects/todo/venv/lib/python3.5/site-packages/django/utils/autoreload.py", line 54, in wrapper
    fn(*args, **kwargs)
  File "/home/abhinandan/PycharmProjects/todo/venv/lib/python3.5/site-packages/django/core/management/commands/runserver.py", line 117, in inner_run
    self.check(display_num_errors=True)
  File "/home/abhinandan/PycharmProjects/todo/venv/lib/python3.5/site-packages/django/core/management/base.py", line 390, in check
    include_deployment_checks=include_deployment_checks,
  File "/home/abhinandan/PycharmProjects/todo/venv/lib/python3.5/site-packages/django/core/management/base.py", line 377, in _run_checks
    return checks.run_checks(**kwargs)
  File "/home/abhinandan/PycharmProjects/todo/venv/lib/python3.5/site-packages/django/core/checks/registry.py", line 72, in run_checks
    new_errors = check(app_configs=app_configs)
  File "/home/abhinandan/PycharmProjects/todo/venv/lib/python3.5/site-packages/django/core/checks/urls.py", line 13, in check_url_config
    return check_resolver(resolver)
  File "/home/abhinandan/PycharmProjects/todo/venv/lib/python3.5/site-packages/django/core/checks/urls.py", line 23, in check_resolver
    return check_method()
  File "/home/abhinandan/PycharmProjects/todo/venv/lib/python3.5/site-packages/django/urls/resolvers.py", line 398, in check
    for pattern in self.url_patterns:
  File "/home/abhinandan/PycharmProjects/todo/venv/lib/python3.5/site-packages/django/utils/functional.py", line 80, in __get__
    res = instance.__dict__[self.name] = self.func(instance)
  File "/home/abhinandan/PycharmProjects/todo/venv/lib/python3.5/site-packages/django/urls/resolvers.py", line 579, in url_patterns
    patterns = getattr(self.urlconf_module, "urlpatterns", self.urlconf_module)
  File "/home/abhinandan/PycharmProjects/todo/venv/lib/python3.5/site-packages/django/utils/functional.py", line 80, in __get__
    res = instance.__dict__[self.name] = self.func(instance)
  File "/home/abhinandan/PycharmProjects/todo/venv/lib/python3.5/site-packages/django/urls/resolvers.py", line 572, in urlconf_module
    return import_module(self.urlconf_name)
  File "/usr/lib/python3.5/importlib/__init__.py", line 126, in import_module
    return _bootstrap._gcd_import(name[level:], package, level)
  File "<frozen importlib._bootstrap>", line 986, in _gcd_import
  File "<frozen importlib._bootstrap>", line 969, in _find_and_load
  File "<frozen importlib._bootstrap>", line 958, in _find_and_load_unlocked
  File "<frozen importlib._bootstrap>", line 673, in _load_unlocked
  File "<frozen importlib._bootstrap_external>", line 665, in exec_module
  File "<frozen importlib._bootstrap>", line 222, in _call_with_frames_removed
  File "/home/abhinandan/PycharmProjects/todo/todo/urls.py", line 22, in <module>
    path('', include('todo_list.urls')),
  File "/home/abhinandan/PycharmProjects/todo/venv/lib/python3.5/site-packages/django/urls/conf.py", line 34, in include
    urlconf_module = import_module(urlconf_module)
  File "/usr/lib/python3.5/importlib/__init__.py", line 126, in import_module
    return _bootstrap._gcd_import(name[level:], package, level)
  File "<frozen importlib._bootstrap>", line 986, in _gcd_import
  File "<frozen importlib._bootstrap>", line 969, in _find_and_load
  File "<frozen importlib._bootstrap>", line 958, in _find_and_load_unlocked
  File "<frozen importlib._bootstrap>", line 673, in _load_unlocked
  File "<frozen importlib._bootstrap_external>", line 665, in exec_module
  File "<frozen importlib._bootstrap>", line 222, in _call_with_frames_removed
  File "/home/abhinandan/PycharmProjects/todo/todo_list/urls.py", line 7, in <module>
    path('cross_off/<list_id>',views.cross_off, name="cross_off"),
AttributeError: module 'todo_list.views' has no attribute 'cross_off'

/home/abhinandan/PycharmProjects/todo/todo_list/urls.py changed, reloading.
Performing system checks...

Watching for file changes with StatReloader
Exception in thread django-main-thread:
Traceback (most recent call last):
  File "/usr/lib/python3.5/threading.py", line 914, in _bootstrap_inner
    self.run()
  File "/usr/lib/python3.5/threading.py", line 862, in run
    self._target(*self._args, **self._kwargs)
  File "/home/abhinandan/PycharmProjects/todo/venv/lib/python3.5/site-packages/django/utils/autoreload.py", line 54, in wrapper
    fn(*args, **kwargs)
  File "/home/abhinandan/PycharmProjects/todo/venv/lib/python3.5/site-packages/django/core/management/commands/runserver.py", line 117, in inner_run
    self.check(display_num_errors=True)
  File "/home/abhinandan/PycharmProjects/todo/venv/lib/python3.5/site-packages/django/core/management/base.py", line 390, in check
    include_deployment_checks=include_deployment_checks,
  File "/home/abhinandan/PycharmProjects/todo/venv/lib/python3.5/site-packages/django/core/management/base.py", line 377, in _run_checks
    return checks.run_checks(**kwargs)
  File "/home/abhinandan/PycharmProjects/todo/venv/lib/python3.5/site-packages/django/core/checks/registry.py", line 72, in run_checks
    new_errors = check(app_configs=app_configs)
  File "/home/abhinandan/PycharmProjects/todo/venv/lib/python3.5/site-packages/django/core/checks/urls.py", line 13, in check_url_config
    return check_resolver(resolver)
  File "/home/abhinandan/PycharmProjects/todo/venv/lib/python3.5/site-packages/django/core/checks/urls.py", line 23, in check_resolver
    return check_method()
  File "/home/abhinandan/PycharmProjects/todo/venv/lib/python3.5/site-packages/django/urls/resolvers.py", line 398, in check
    for pattern in self.url_patterns:
  File "/home/abhinandan/PycharmProjects/todo/venv/lib/python3.5/site-packages/django/utils/functional.py", line 80, in __get__
    res = instance.__dict__[self.name] = self.func(instance)
  File "/home/abhinandan/PycharmProjects/todo/venv/lib/python3.5/site-packages/django/urls/resolvers.py", line 579, in url_patterns
    patterns = getattr(self.urlconf_module, "urlpatterns", self.urlconf_module)
  File "/home/abhinandan/PycharmProjects/todo/venv/lib/python3.5/site-packages/django/utils/functional.py", line 80, in __get__
    res = instance.__dict__[self.name] = self.func(instance)
  File "/home/abhinandan/PycharmProjects/todo/venv/lib/python3.5/site-packages/django/urls/resolvers.py", line 572, in urlconf_module
    return import_module(self.urlconf_name)
  File "/usr/lib/python3.5/importlib/__init__.py", line 126, in import_module
    return _bootstrap._gcd_import(name[level:], package, level)
  File "<frozen importlib._bootstrap>", line 986, in _gcd_import
  File "<frozen importlib._bootstrap>", line 969, in _find_and_load
  File "<frozen importlib._bootstrap>", line 958, in _find_and_load_unlocked
  File "<frozen importlib._bootstrap>", line 673, in _load_unlocked
  File "<frozen importlib._bootstrap_external>", line 665, in exec_module
  File "<frozen importlib._bootstrap>", line 222, in _call_with_frames_removed
  File "/home/abhinandan/PycharmProjects/todo/todo/urls.py", line 22, in <module>
    path('', include('todo_list.urls')),
  File "/home/abhinandan/PycharmProjects/todo/venv/lib/python3.5/site-packages/django/urls/conf.py", line 34, in include
    urlconf_module = import_module(urlconf_module)
  File "/usr/lib/python3.5/importlib/__init__.py", line 126, in import_module
    return _bootstrap._gcd_import(name[level:], package, level)
  File "<frozen importlib._bootstrap>", line 986, in _gcd_import
  File "<frozen importlib._bootstrap>", line 969, in _find_and_load
  File "<frozen importlib._bootstrap>", line 958, in _find_and_load_unlocked
  File "<frozen importlib._bootstrap>", line 673, in _load_unlocked
  File "<frozen importlib._bootstrap_external>", line 665, in exec_module
  File "<frozen importlib._bootstrap>", line 222, in _call_with_frames_removed
  File "/home/abhinandan/PycharmProjects/todo/todo_list/urls.py", line 8, in <module>
    path('uncross/<list_id>',views.uncross, name="uncross"),
AttributeError: module 'todo_list.views' has no attribute 'uncross'

/home/abhinandan/PycharmProjects/todo/todo_list/views.py changed, reloading.
Performing system checks...

Watching for file changes with StatReloader
/home/abhinandan/PycharmProjects/todo/todo_list/views.py changed, reloading.
Performing system checks...

System check identified no issues (0 silenced).
August 07, 2019 - 09:20:55
Django version 2.2.4, using settings 'todo.settings'
Starting development server at http://127.0.0.1:7000/
Quit the server with CONTROL-C.
Watching for file changes with StatReloader
/home/abhinandan/PycharmProjects/todo/todo_list/views.py changed, reloading.
Performing system checks...

System check identified no issues (0 silenced).
August 07, 2019 - 09:21:12
Django version 2.2.4, using settings 'todo.settings'
Starting development server at http://127.0.0.1:7000/
Quit the server with CONTROL-C.
Watching for file changes with StatReloader
/home/abhinandan/PycharmProjects/todo/todo_list/views.py changed, reloading.
Performing system checks...

System check identified no issues (0 silenced).
August 07, 2019 - 09:21:47
Django version 2.2.4, using settings 'todo.settings'
Starting development server at http://127.0.0.1:7000/
Quit the server with CONTROL-C.
Watching for file changes with StatReloader
/home/abhinandan/PycharmProjects/todo/todo_list/views.py changed, reloading.
Performing system checks...

System check identified no issues (0 silenced).
August 07, 2019 - 09:22:00
Django version 2.2.4, using settings 'todo.settings'
Starting development server at http://127.0.0.1:7000/
Quit the server with CONTROL-C.
Watching for file changes with StatReloader
/home/abhinandan/PycharmProjects/todo/todo_list/views.py changed, reloading.
Performing system checks...

System check identified no issues (0 silenced).
August 07, 2019 - 09:22:12
Django version 2.2.4, using settings 'todo.settings'
Starting development server at http://127.0.0.1:7000/
Quit the server with CONTROL-C.
Watching for file changes with StatReloader
/home/abhinandan/PycharmProjects/todo/todo_list/views.py changed, reloading.
Performing system checks...

System check identified no issues (0 silenced).
August 07, 2019 - 09:22:27
Django version 2.2.4, using settings 'todo.settings'
Starting development server at http://127.0.0.1:7000/
Quit the server with CONTROL-C.
Watching for file changes with StatReloader
[07/Aug/2019 09:26:49] "GET / HTTP/1.1" 200 3268
[07/Aug/2019 09:29:01] "GET / HTTP/1.1" 200 3322
[07/Aug/2019 09:29:05] "GET /cross_off/2 HTTP/1.1" 302 0
[07/Aug/2019 09:29:05] "GET / HTTP/1.1" 200 3342
[07/Aug/2019 09:29:07] "GET /uncross/2 HTTP/1.1" 302 0
[07/Aug/2019 09:29:07] "GET / HTTP/1.1" 200 3322
/home/abhinandan/PycharmProjects/todo/todo/settings.py changed, reloading.
Performing system checks...

System check identified no issues (0 silenced).
August 07, 2019 - 09:22:42
Django version 2.2.4, using settings 'todo.settings'
Starting development server at http://127.0.0.1:7000/
Quit the server with CONTROL-C.
Watching for file changes with StatReloader
/home/abhinandan/PycharmProjects/todo/todo/settings.py changed, reloading.
Performing system checks...

System check identified no issues (0 silenced).
August 07, 2019 - 09:30:00
Django version 2.2.4, using settings 'todo.settings'
Starting development server at http://127.0.0.1:7000/
Quit the server with CONTROL-C.
Traceback (most recent call last):
  File "manage.py", line 21, in <module>
    main()
  File "manage.py", line 17, in main
    execute_from_command_line(sys.argv)
  File "/home/abhinandan/PycharmProjects/todo/venv/lib/python3.5/site-packages/django/core/management/__init__.py", line 381, in execute_from_command_line
    utility.execute()
  File "/home/abhinandan/PycharmProjects/todo/venv/lib/python3.5/site-packages/django/core/management/__init__.py", line 325, in execute
    settings.INSTALLED_APPS
  File "/home/abhinandan/PycharmProjects/todo/venv/lib/python3.5/site-packages/django/conf/__init__.py", line 79, in __getattr__
    self._setup(name)
  File "/home/abhinandan/PycharmProjects/todo/venv/lib/python3.5/site-packages/django/conf/__init__.py", line 66, in _setup
    self._wrapped = Settings(settings_module)
  File "/home/abhinandan/PycharmProjects/todo/venv/lib/python3.5/site-packages/django/conf/__init__.py", line 157, in __init__
    mod = importlib.import_module(self.SETTINGS_MODULE)
  File "/usr/lib/python3.5/importlib/__init__.py", line 126, in import_module
    return _bootstrap._gcd_import(name[level:], package, level)
  File "<frozen importlib._bootstrap>", line 986, in _gcd_import
  File "<frozen importlib._bootstrap>", line 969, in _find_and_load
  File "<frozen importlib._bootstrap>", line 958, in _find_and_load_unlocked
  File "<frozen importlib._bootstrap>", line 673, in _load_unlocked
  File "<frozen importlib._bootstrap_external>", line 661, in exec_module
  File "<frozen importlib._bootstrap_external>", line 767, in get_code
  File "<frozen importlib._bootstrap_external>", line 727, in source_to_code
  File "<frozen importlib._bootstrap>", line 222, in _call_with_frames_removed
  File "/home/abhinandan/PycharmProjects/todo/todo/settings.py", line 124
    STATICFILES_DIR=    
                       ^
SyntaxError: invalid syntax
Watching for file changes with StatReloader
Internal Server Error: /
Traceback (most recent call last):
  File "/home/abhinandan/PycharmProjects/todo/venv/lib/python3.5/site-packages/django/template/base.py", line 470, in parse
    compile_func = self.tags[command]
KeyError: 'static'

During handling of the above exception, another exception occurred:

Traceback (most recent call last):
  File "/home/abhinandan/PycharmProjects/todo/venv/lib/python3.5/site-packages/django/core/handlers/exception.py", line 34, in inner
    response = get_response(request)
  File "/home/abhinandan/PycharmProjects/todo/venv/lib/python3.5/site-packages/django/core/handlers/base.py", line 115, in _get_response
    response = self.process_exception_by_middleware(e, request)
  File "/home/abhinandan/PycharmProjects/todo/venv/lib/python3.5/site-packages/django/core/handlers/base.py", line 113, in _get_response
    response = wrapped_callback(request, *callback_args, **callback_kwargs)
  File "/home/abhinandan/PycharmProjects/todo/todo_list/views.py", line 17, in home
    return render(request, "home.html", {"all_items": all_items})
  File "/home/abhinandan/PycharmProjects/todo/venv/lib/python3.5/site-packages/django/shortcuts.py", line 36, in render
    content = loader.render_to_string(template_name, context, request, using=using)
  File "/home/abhinandan/PycharmProjects/todo/venv/lib/python3.5/site-packages/django/template/loader.py", line 62, in render_to_string
    return template.render(context, request)
  File "/home/abhinandan/PycharmProjects/todo/venv/lib/python3.5/site-packages/django/template/backends/django.py", line 61, in render
    return self.template.render(context)
  File "/home/abhinandan/PycharmProjects/todo/venv/lib/python3.5/site-packages/django/template/base.py", line 171, in render
    return self._render(context)
  File "/home/abhinandan/PycharmProjects/todo/venv/lib/python3.5/site-packages/django/template/base.py", line 163, in _render
    return self.nodelist.render(context)
  File "/home/abhinandan/PycharmProjects/todo/venv/lib/python3.5/site-packages/django/template/base.py", line 937, in render
    bit = node.render_annotated(context)
  File "/home/abhinandan/PycharmProjects/todo/venv/lib/python3.5/site-packages/django/template/base.py", line 904, in render_annotated
    return self.render(context)
  File "/home/abhinandan/PycharmProjects/todo/venv/lib/python3.5/site-packages/django/template/loader_tags.py", line 127, in render
    compiled_parent = self.get_parent(context)
  File "/home/abhinandan/PycharmProjects/todo/venv/lib/python3.5/site-packages/django/template/loader_tags.py", line 124, in get_parent
    return self.find_template(parent, context)
  File "/home/abhinandan/PycharmProjects/todo/venv/lib/python3.5/site-packages/django/template/loader_tags.py", line 104, in find_template
    template_name, skip=history,
  File "/home/abhinandan/PycharmProjects/todo/venv/lib/python3.5/site-packages/django/template/engine.py", line 125, in find_template
    template = loader.get_template(name, skip=skip)
  File "/home/abhinandan/PycharmProjects/todo/venv/lib/python3.5/site-packages/django/template/loaders/base.py", line 30, in get_template
    contents, origin, origin.template_name, self.engine,
  File "/home/abhinandan/PycharmProjects/todo/venv/lib/python3.5/site-packages/django/template/base.py", line 156, in __init__
    self.nodelist = self.compile_nodelist()
  File "/home/abhinandan/PycharmProjects/todo/venv/lib/python3.5/site-packages/django/template/base.py", line 194, in compile_nodelist
    return parser.parse()
  File "/home/abhinandan/PycharmProjects/todo/venv/lib/python3.5/site-packages/django/template/base.py", line 472, in parse
    self.invalid_block_tag(token, command, parse_until)
  File "/home/abhinandan/PycharmProjects/todo/venv/lib/python3.5/site-packages/django/template/base.py", line 534, in invalid_block_tag
    "or load this tag?" % (token.lineno, command)
django.template.exceptions.TemplateSyntaxError: Invalid block tag on line 11: 'static'. Did you forget to register or load this tag?
[07/Aug/2019 09:36:20] "GET / HTTP/1.1" 500 161871
[07/Aug/2019 09:37:48] "GET / HTTP/1.1" 200 3379
[07/Aug/2019 09:37:48] "GET /static/css/my_css.css HTTP/1.1" 200 47
[07/Aug/2019 09:37:50] "GET /cross_off/2 HTTP/1.1" 302 0
[07/Aug/2019 09:37:50] "GET / HTTP/1.1" 200 3419
/home/abhinandan/PycharmProjects/todo/todo_list/views.py changed, reloading.
Performing system checks...

System check identified no issues (0 silenced).
August 07, 2019 - 09:36:16
Django version 2.2.4, using settings 'todo.settings'
Starting development server at http://127.0.0.1:7000/
Quit the server with CONTROL-C.
Watching for file changes with StatReloader
/home/abhinandan/PycharmProjects/todo/todo_list/views.py changed, reloading.
Performing system checks...

System check identified no issues (0 silenced).
August 07, 2019 - 09:38:08
Django version 2.2.4, using settings 'todo.settings'
Starting development server at http://127.0.0.1:7000/
Quit the server with CONTROL-C.
Watching for file changes with StatReloader
/home/abhinandan/PycharmProjects/todo/todo_list/urls.py changed, reloading.
Performing system checks...

System check identified no issues (0 silenced).
August 07, 2019 - 09:39:00
Django version 2.2.4, using settings 'todo.settings'
Starting development server at http://127.0.0.1:7000/
Quit the server with CONTROL-C.
Watching for file changes with StatReloader
/home/abhinandan/PycharmProjects/todo/todo_list/views.py changed, reloading.
Performing system checks...

System check identified no issues (0 silenced).
August 07, 2019 - 09:39:16
Django version 2.2.4, using settings 'todo.settings'
Starting development server at http://127.0.0.1:7000/
Quit the server with CONTROL-C.
Watching for file changes with StatReloader
/home/abhinandan/PycharmProjects/todo/todo_list/views.py changed, reloading.
Performing system checks...

System check identified no issues (0 silenced).
August 07, 2019 - 09:39:33
Django version 2.2.4, using settings 'todo.settings'
Starting development server at http://127.0.0.1:7000/
Quit the server with CONTROL-C.
Watching for file changes with StatReloader
/home/abhinandan/PycharmProjects/todo/todo_list/views.py changed, reloading.
Performing system checks...

System check identified no issues (0 silenced).
August 07, 2019 - 09:39:50
Django version 2.2.4, using settings 'todo.settings'
Starting development server at http://127.0.0.1:7000/
Quit the server with CONTROL-C.
Watching for file changes with StatReloader
Exception in thread django-main-thread:
Traceback (most recent call last):
  File "/usr/lib/python3.5/threading.py", line 914, in _bootstrap_inner
    self.run()
  File "/usr/lib/python3.5/threading.py", line 862, in run
    self._target(*self._args, **self._kwargs)
  File "/home/abhinandan/PycharmProjects/todo/venv/lib/python3.5/site-packages/django/utils/autoreload.py", line 54, in wrapper
    fn(*args, **kwargs)
  File "/home/abhinandan/PycharmProjects/todo/venv/lib/python3.5/site-packages/django/core/management/commands/runserver.py", line 117, in inner_run
    self.check(display_num_errors=True)
  File "/home/abhinandan/PycharmProjects/todo/venv/lib/python3.5/site-packages/django/core/management/base.py", line 390, in check
    include_deployment_checks=include_deployment_checks,
  File "/home/abhinandan/PycharmProjects/todo/venv/lib/python3.5/site-packages/django/core/management/base.py", line 377, in _run_checks
    return checks.run_checks(**kwargs)
  File "/home/abhinandan/PycharmProjects/todo/venv/lib/python3.5/site-packages/django/core/checks/registry.py", line 72, in run_checks
    new_errors = check(app_configs=app_configs)
  File "/home/abhinandan/PycharmProjects/todo/venv/lib/python3.5/site-packages/django/core/checks/urls.py", line 40, in check_url_namespaces_unique
    all_namespaces = _load_all_namespaces(resolver)
  File "/home/abhinandan/PycharmProjects/todo/venv/lib/python3.5/site-packages/django/core/checks/urls.py", line 57, in _load_all_namespaces
    url_patterns = getattr(resolver, 'url_patterns', [])
  File "/home/abhinandan/PycharmProjects/todo/venv/lib/python3.5/site-packages/django/utils/functional.py", line 80, in __get__
    res = instance.__dict__[self.name] = self.func(instance)
  File "/home/abhinandan/PycharmProjects/todo/venv/lib/python3.5/site-packages/django/urls/resolvers.py", line 579, in url_patterns
    patterns = getattr(self.urlconf_module, "urlpatterns", self.urlconf_module)
  File "/home/abhinandan/PycharmProjects/todo/venv/lib/python3.5/site-packages/django/utils/functional.py", line 80, in __get__
    res = instance.__dict__[self.name] = self.func(instance)
  File "/home/abhinandan/PycharmProjects/todo/venv/lib/python3.5/site-packages/django/urls/resolvers.py", line 572, in urlconf_module
    return import_module(self.urlconf_name)
  File "/usr/lib/python3.5/importlib/__init__.py", line 126, in import_module
    return _bootstrap._gcd_import(name[level:], package, level)
  File "<frozen importlib._bootstrap>", line 986, in _gcd_import
  File "<frozen importlib._bootstrap>", line 969, in _find_and_load
  File "<frozen importlib._bootstrap>", line 958, in _find_and_load_unlocked
  File "<frozen importlib._bootstrap>", line 673, in _load_unlocked
  File "<frozen importlib._bootstrap_external>", line 665, in exec_module
  File "<frozen importlib._bootstrap>", line 222, in _call_with_frames_removed
  File "/home/abhinandan/PycharmProjects/todo/todo/urls.py", line 18, in <module>
    from todo_list import views
  File "/home/abhinandan/PycharmProjects/todo/todo_list/views.py", line 42
    if request.method == ''
                          ^
SyntaxError: invalid syntax

/home/abhinandan/PycharmProjects/todo/todo_list/views.py changed, reloading.
Performing system checks...

Watching for file changes with StatReloader
Exception in thread django-main-thread:
Traceback (most recent call last):
  File "/usr/lib/python3.5/threading.py", line 914, in _bootstrap_inner
    self.run()
  File "/usr/lib/python3.5/threading.py", line 862, in run
    self._target(*self._args, **self._kwargs)
  File "/home/abhinandan/PycharmProjects/todo/venv/lib/python3.5/site-packages/django/utils/autoreload.py", line 54, in wrapper
    fn(*args, **kwargs)
  File "/home/abhinandan/PycharmProjects/todo/venv/lib/python3.5/site-packages/django/core/management/commands/runserver.py", line 117, in inner_run
    self.check(display_num_errors=True)
  File "/home/abhinandan/PycharmProjects/todo/venv/lib/python3.5/site-packages/django/core/management/base.py", line 390, in check
    include_deployment_checks=include_deployment_checks,
  File "/home/abhinandan/PycharmProjects/todo/venv/lib/python3.5/site-packages/django/core/management/base.py", line 377, in _run_checks
    return checks.run_checks(**kwargs)
  File "/home/abhinandan/PycharmProjects/todo/venv/lib/python3.5/site-packages/django/core/checks/registry.py", line 72, in run_checks
    new_errors = check(app_configs=app_configs)
  File "/home/abhinandan/PycharmProjects/todo/venv/lib/python3.5/site-packages/django/core/checks/urls.py", line 40, in check_url_namespaces_unique
    all_namespaces = _load_all_namespaces(resolver)
  File "/home/abhinandan/PycharmProjects/todo/venv/lib/python3.5/site-packages/django/core/checks/urls.py", line 57, in _load_all_namespaces
    url_patterns = getattr(resolver, 'url_patterns', [])
  File "/home/abhinandan/PycharmProjects/todo/venv/lib/python3.5/site-packages/django/utils/functional.py", line 80, in __get__
    res = instance.__dict__[self.name] = self.func(instance)
  File "/home/abhinandan/PycharmProjects/todo/venv/lib/python3.5/site-packages/django/urls/resolvers.py", line 579, in url_patterns
    patterns = getattr(self.urlconf_module, "urlpatterns", self.urlconf_module)
  File "/home/abhinandan/PycharmProjects/todo/venv/lib/python3.5/site-packages/django/utils/functional.py", line 80, in __get__
    res = instance.__dict__[self.name] = self.func(instance)
  File "/home/abhinandan/PycharmProjects/todo/venv/lib/python3.5/site-packages/django/urls/resolvers.py", line 572, in urlconf_module
    return import_module(self.urlconf_name)
  File "/usr/lib/python3.5/importlib/__init__.py", line 126, in import_module
    return _bootstrap._gcd_import(name[level:], package, level)
  File "<frozen importlib._bootstrap>", line 986, in _gcd_import
  File "<frozen importlib._bootstrap>", line 969, in _find_and_load
  File "<frozen importlib._bootstrap>", line 958, in _find_and_load_unlocked
  File "<frozen importlib._bootstrap>", line 673, in _load_unlocked
  File "<frozen importlib._bootstrap_external>", line 665, in exec_module
  File "<frozen importlib._bootstrap>", line 222, in _call_with_frames_removed
  File "/home/abhinandan/PycharmProjects/todo/todo/urls.py", line 18, in <module>
    from todo_list import views
  File "/home/abhinandan/PycharmProjects/todo/todo_list/views.py", line 44
    return render
         ^
IndentationError: expected an indented block

/home/abhinandan/PycharmProjects/todo/todo_list/views.py changed, reloading.
Performing system checks...

Watching for file changes with StatReloader
Exception in thread django-main-thread:
Traceback (most recent call last):
  File "/usr/lib/python3.5/threading.py", line 914, in _bootstrap_inner
    self.run()
  File "/usr/lib/python3.5/threading.py", line 862, in run
    self._target(*self._args, **self._kwargs)
  File "/home/abhinandan/PycharmProjects/todo/venv/lib/python3.5/site-packages/django/utils/autoreload.py", line 54, in wrapper
    fn(*args, **kwargs)
  File "/home/abhinandan/PycharmProjects/todo/venv/lib/python3.5/site-packages/django/core/management/commands/runserver.py", line 117, in inner_run
    self.check(display_num_errors=True)
  File "/home/abhinandan/PycharmProjects/todo/venv/lib/python3.5/site-packages/django/core/management/base.py", line 390, in check
    include_deployment_checks=include_deployment_checks,
  File "/home/abhinandan/PycharmProjects/todo/venv/lib/python3.5/site-packages/django/core/management/base.py", line 377, in _run_checks
    return checks.run_checks(**kwargs)
  File "/home/abhinandan/PycharmProjects/todo/venv/lib/python3.5/site-packages/django/core/checks/registry.py", line 72, in run_checks
    new_errors = check(app_configs=app_configs)
  File "/home/abhinandan/PycharmProjects/todo/venv/lib/python3.5/site-packages/django/core/checks/urls.py", line 40, in check_url_namespaces_unique
    all_namespaces = _load_all_namespaces(resolver)
  File "/home/abhinandan/PycharmProjects/todo/venv/lib/python3.5/site-packages/django/core/checks/urls.py", line 57, in _load_all_namespaces
    url_patterns = getattr(resolver, 'url_patterns', [])
  File "/home/abhinandan/PycharmProjects/todo/venv/lib/python3.5/site-packages/django/utils/functional.py", line 80, in __get__
    res = instance.__dict__[self.name] = self.func(instance)
  File "/home/abhinandan/PycharmProjects/todo/venv/lib/python3.5/site-packages/django/urls/resolvers.py", line 579, in url_patterns
    patterns = getattr(self.urlconf_module, "urlpatterns", self.urlconf_module)
  File "/home/abhinandan/PycharmProjects/todo/venv/lib/python3.5/site-packages/django/utils/functional.py", line 80, in __get__
    res = instance.__dict__[self.name] = self.func(instance)
  File "/home/abhinandan/PycharmProjects/todo/venv/lib/python3.5/site-packages/django/urls/resolvers.py", line 572, in urlconf_module
    return import_module(self.urlconf_name)
  File "/usr/lib/python3.5/importlib/__init__.py", line 126, in import_module
    return _bootstrap._gcd_import(name[level:], package, level)
  File "<frozen importlib._bootstrap>", line 986, in _gcd_import
  File "<frozen importlib._bootstrap>", line 969, in _find_and_load
  File "<frozen importlib._bootstrap>", line 958, in _find_and_load_unlocked
  File "<frozen importlib._bootstrap>", line 673, in _load_unlocked
  File "<frozen importlib._bootstrap_external>", line 665, in exec_module
  File "<frozen importlib._bootstrap>", line 222, in _call_with_frames_removed
  File "/home/abhinandan/PycharmProjects/todo/todo/urls.py", line 18, in <module>
    from todo_list import views
  File "/home/abhinandan/PycharmProjects/todo/todo_list/views.py", line 43
    item =
          ^
SyntaxError: invalid syntax

/home/abhinandan/PycharmProjects/todo/todo_list/views.py changed, reloading.
Performing system checks...

Watching for file changes with StatReloader
/home/abhinandan/PycharmProjects/todo/todo_list/views.py changed, reloading.
Performing system checks...

System check identified no issues (0 silenced).
August 07, 2019 - 09:40:56
Django version 2.2.4, using settings 'todo.settings'
Starting development server at http://127.0.0.1:7000/
Quit the server with CONTROL-C.
Watching for file changes with StatReloader
Exception in thread django-main-thread:
Traceback (most recent call last):
  File "/usr/lib/python3.5/threading.py", line 914, in _bootstrap_inner
    self.run()
  File "/usr/lib/python3.5/threading.py", line 862, in run
    self._target(*self._args, **self._kwargs)
  File "/home/abhinandan/PycharmProjects/todo/venv/lib/python3.5/site-packages/django/utils/autoreload.py", line 54, in wrapper
    fn(*args, **kwargs)
  File "/home/abhinandan/PycharmProjects/todo/venv/lib/python3.5/site-packages/django/core/management/commands/runserver.py", line 117, in inner_run
    self.check(display_num_errors=True)
  File "/home/abhinandan/PycharmProjects/todo/venv/lib/python3.5/site-packages/django/core/management/base.py", line 390, in check
    include_deployment_checks=include_deployment_checks,
  File "/home/abhinandan/PycharmProjects/todo/venv/lib/python3.5/site-packages/django/core/management/base.py", line 377, in _run_checks
    return checks.run_checks(**kwargs)
  File "/home/abhinandan/PycharmProjects/todo/venv/lib/python3.5/site-packages/django/core/checks/registry.py", line 72, in run_checks
    new_errors = check(app_configs=app_configs)
  File "/home/abhinandan/PycharmProjects/todo/venv/lib/python3.5/site-packages/django/core/checks/urls.py", line 40, in check_url_namespaces_unique
    all_namespaces = _load_all_namespaces(resolver)
  File "/home/abhinandan/PycharmProjects/todo/venv/lib/python3.5/site-packages/django/core/checks/urls.py", line 57, in _load_all_namespaces
    url_patterns = getattr(resolver, 'url_patterns', [])
  File "/home/abhinandan/PycharmProjects/todo/venv/lib/python3.5/site-packages/django/utils/functional.py", line 80, in __get__
    res = instance.__dict__[self.name] = self.func(instance)
  File "/home/abhinandan/PycharmProjects/todo/venv/lib/python3.5/site-packages/django/urls/resolvers.py", line 579, in url_patterns
    patterns = getattr(self.urlconf_module, "urlpatterns", self.urlconf_module)
  File "/home/abhinandan/PycharmProjects/todo/venv/lib/python3.5/site-packages/django/utils/functional.py", line 80, in __get__
    res = instance.__dict__[self.name] = self.func(instance)
  File "/home/abhinandan/PycharmProjects/todo/venv/lib/python3.5/site-packages/django/urls/resolvers.py", line 572, in urlconf_module
    return import_module(self.urlconf_name)
  File "/usr/lib/python3.5/importlib/__init__.py", line 126, in import_module
    return _bootstrap._gcd_import(name[level:], package, level)
  File "<frozen importlib._bootstrap>", line 986, in _gcd_import
  File "<frozen importlib._bootstrap>", line 969, in _find_and_load
  File "<frozen importlib._bootstrap>", line 958, in _find_and_load_unlocked
  File "<frozen importlib._bootstrap>", line 673, in _load_unlocked
  File "<frozen importlib._bootstrap_external>", line 665, in exec_module
  File "<frozen importlib._bootstrap>", line 222, in _call_with_frames_removed
  File "/home/abhinandan/PycharmProjects/todo/todo/urls.py", line 18, in <module>
    from todo_list import views
  File "/home/abhinandan/PycharmProjects/todo/todo_list/views.py", line 44
    form =
          ^
SyntaxError: invalid syntax

/home/abhinandan/PycharmProjects/todo/todo_list/views.py changed, reloading.
Performing system checks...

Watching for file changes with StatReloader
/home/abhinandan/PycharmProjects/todo/todo_list/views.py changed, reloading.
Performing system checks...

System check identified no issues (0 silenced).
August 07, 2019 - 09:41:11
Django version 2.2.4, using settings 'todo.settings'
Starting development server at http://127.0.0.1:7000/
Quit the server with CONTROL-C.
Watching for file changes with StatReloader
/home/abhinandan/PycharmProjects/todo/todo_list/views.py changed, reloading.
Performing system checks...

System check identified no issues (0 silenced).
August 07, 2019 - 09:41:20
Django version 2.2.4, using settings 'todo.settings'
Starting development server at http://127.0.0.1:7000/
Quit the server with CONTROL-C.
Watching for file changes with StatReloader
/home/abhinandan/PycharmProjects/todo/todo_list/views.py changed, reloading.
Performing system checks...

System check identified no issues (0 silenced).
August 07, 2019 - 09:41:25
Django version 2.2.4, using settings 'todo.settings'
Starting development server at http://127.0.0.1:7000/
Quit the server with CONTROL-C.
Watching for file changes with StatReloader
/home/abhinandan/PycharmProjects/todo/todo_list/views.py changed, reloading.
Performing system checks...

System check identified no issues (0 silenced).
August 07, 2019 - 09:41:38
Django version 2.2.4, using settings 'todo.settings'
Starting development server at http://127.0.0.1:7000/
Quit the server with CONTROL-C.
Watching for file changes with StatReloader
/home/abhinandan/PycharmProjects/todo/todo_list/views.py changed, reloading.
Performing system checks...

System check identified no issues (0 silenced).
August 07, 2019 - 09:41:56
Django version 2.2.4, using settings 'todo.settings'
Starting development server at http://127.0.0.1:7000/
Quit the server with CONTROL-C.
Watching for file changes with StatReloader
/home/abhinandan/PycharmProjects/todo/todo_list/views.py changed, reloading.
Performing system checks...

System check identified no issues (0 silenced).
August 07, 2019 - 09:42:06
Django version 2.2.4, using settings 'todo.settings'
Starting development server at http://127.0.0.1:7000/
Quit the server with CONTROL-C.
Watching for file changes with StatReloader
/home/abhinandan/PycharmProjects/todo/todo_list/views.py changed, reloading.
Performing system checks...

System check identified no issues (0 silenced).
August 07, 2019 - 09:42:34
Django version 2.2.4, using settings 'todo.settings'
Starting development server at http://127.0.0.1:7000/
Quit the server with CONTROL-C.
Watching for file changes with StatReloader
Exception in thread django-main-thread:
Traceback (most recent call last):
  File "/usr/lib/python3.5/threading.py", line 914, in _bootstrap_inner
    self.run()
  File "/usr/lib/python3.5/threading.py", line 862, in run
    self._target(*self._args, **self._kwargs)
  File "/home/abhinandan/PycharmProjects/todo/venv/lib/python3.5/site-packages/django/utils/autoreload.py", line 54, in wrapper
    fn(*args, **kwargs)
  File "/home/abhinandan/PycharmProjects/todo/venv/lib/python3.5/site-packages/django/core/management/commands/runserver.py", line 117, in inner_run
    self.check(display_num_errors=True)
  File "/home/abhinandan/PycharmProjects/todo/venv/lib/python3.5/site-packages/django/core/management/base.py", line 390, in check
    include_deployment_checks=include_deployment_checks,
  File "/home/abhinandan/PycharmProjects/todo/venv/lib/python3.5/site-packages/django/core/management/base.py", line 377, in _run_checks
    return checks.run_checks(**kwargs)
  File "/home/abhinandan/PycharmProjects/todo/venv/lib/python3.5/site-packages/django/core/checks/registry.py", line 72, in run_checks
    new_errors = check(app_configs=app_configs)
  File "/home/abhinandan/PycharmProjects/todo/venv/lib/python3.5/site-packages/django/core/checks/urls.py", line 40, in check_url_namespaces_unique
    all_namespaces = _load_all_namespaces(resolver)
  File "/home/abhinandan/PycharmProjects/todo/venv/lib/python3.5/site-packages/django/core/checks/urls.py", line 57, in _load_all_namespaces
    url_patterns = getattr(resolver, 'url_patterns', [])
  File "/home/abhinandan/PycharmProjects/todo/venv/lib/python3.5/site-packages/django/utils/functional.py", line 80, in __get__
    res = instance.__dict__[self.name] = self.func(instance)
  File "/home/abhinandan/PycharmProjects/todo/venv/lib/python3.5/site-packages/django/urls/resolvers.py", line 579, in url_patterns
    patterns = getattr(self.urlconf_module, "urlpatterns", self.urlconf_module)
  File "/home/abhinandan/PycharmProjects/todo/venv/lib/python3.5/site-packages/django/utils/functional.py", line 80, in __get__
    res = instance.__dict__[self.name] = self.func(instance)
  File "/home/abhinandan/PycharmProjects/todo/venv/lib/python3.5/site-packages/django/urls/resolvers.py", line 572, in urlconf_module
    return import_module(self.urlconf_name)
  File "/usr/lib/python3.5/importlib/__init__.py", line 126, in import_module
    return _bootstrap._gcd_import(name[level:], package, level)
  File "<frozen importlib._bootstrap>", line 986, in _gcd_import
  File "<frozen importlib._bootstrap>", line 969, in _find_and_load
  File "<frozen importlib._bootstrap>", line 958, in _find_and_load_unlocked
  File "<frozen importlib._bootstrap>", line 673, in _load_unlocked
  File "<frozen importlib._bootstrap_external>", line 665, in exec_module
  File "<frozen importlib._bootstrap>", line 222, in _call_with_frames_removed
  File "/home/abhinandan/PycharmProjects/todo/todo/urls.py", line 18, in <module>
    from todo_list import views
  File "/home/abhinandan/PycharmProjects/todo/todo_list/views.py", line 52
    
    ^
SyntaxError: unexpected EOF while parsing

/home/abhinandan/PycharmProjects/todo/todo_list/views.py changed, reloading.
Performing system checks...

Watching for file changes with StatReloader
/home/abhinandan/PycharmProjects/todo/todo_list/views.py changed, reloading.
Performing system checks...

System check identified no issues (0 silenced).
August 07, 2019 - 09:43:22
Django version 2.2.4, using settings 'todo.settings'
Starting development server at http://127.0.0.1:7000/
Quit the server with CONTROL-C.
Watching for file changes with StatReloader
/home/abhinandan/PycharmProjects/todo/todo_list/views.py changed, reloading.
Performing system checks...

System check identified no issues (0 silenced).
August 07, 2019 - 09:43:29
Django version 2.2.4, using settings 'todo.settings'
Starting development server at http://127.0.0.1:7000/
Quit the server with CONTROL-C.
Watching for file changes with StatReloader
/home/abhinandan/PycharmProjects/todo/todo_list/views.py changed, reloading.
Performing system checks...

System check identified no issues (0 silenced).
August 07, 2019 - 09:43:48
Django version 2.2.4, using settings 'todo.settings'
Starting development server at http://127.0.0.1:7000/
Quit the server with CONTROL-C.
Watching for file changes with StatReloader
[07/Aug/2019 09:53:25] "GET / HTTP/1.1" 200 3460
[07/Aug/2019 09:53:25] "GET /static/css/my_css.css HTTP/1.1" 304 0
[07/Aug/2019 09:53:27] "GET /edit/1 HTTP/1.1" 200 3119
[07/Aug/2019 09:53:32] "POST / HTTP/1.1" 200 4323
Internal Server Error: /edit/1
Traceback (most recent call last):
  File "/home/abhinandan/PycharmProjects/todo/venv/lib/python3.5/site-packages/django/core/handlers/exception.py", line 34, in inner
    response = get_response(request)
  File "/home/abhinandan/PycharmProjects/todo/venv/lib/python3.5/site-packages/django/core/handlers/base.py", line 115, in _get_response
    response = self.process_exception_by_middleware(e, request)
  File "/home/abhinandan/PycharmProjects/todo/venv/lib/python3.5/site-packages/django/core/handlers/base.py", line 113, in _get_response
    response = wrapped_callback(request, *callback_args, **callback_kwargs)
  File "/home/abhinandan/PycharmProjects/todo/todo_list/views.py", line 53, in edit
    return render(request,"edit.html",{'item':item})
  File "/home/abhinandan/PycharmProjects/todo/venv/lib/python3.5/site-packages/django/shortcuts.py", line 36, in render
    content = loader.render_to_string(template_name, context, request, using=using)
  File "/home/abhinandan/PycharmProjects/todo/venv/lib/python3.5/site-packages/django/template/loader.py", line 62, in render_to_string
    return template.render(context, request)
  File "/home/abhinandan/PycharmProjects/todo/venv/lib/python3.5/site-packages/django/template/backends/django.py", line 61, in render
    return self.template.render(context)
  File "/home/abhinandan/PycharmProjects/todo/venv/lib/python3.5/site-packages/django/template/base.py", line 171, in render
    return self._render(context)
  File "/home/abhinandan/PycharmProjects/todo/venv/lib/python3.5/site-packages/django/template/base.py", line 163, in _render
    return self.nodelist.render(context)
  File "/home/abhinandan/PycharmProjects/todo/venv/lib/python3.5/site-packages/django/template/base.py", line 937, in render
    bit = node.render_annotated(context)
  File "/home/abhinandan/PycharmProjects/todo/venv/lib/python3.5/site-packages/django/template/base.py", line 904, in render_annotated
    return self.render(context)
  File "/home/abhinandan/PycharmProjects/todo/venv/lib/python3.5/site-packages/django/template/loader_tags.py", line 150, in render
    return compiled_parent._render(context)
  File "/home/abhinandan/PycharmProjects/todo/venv/lib/python3.5/site-packages/django/template/base.py", line 163, in _render
    return self.nodelist.render(context)
  File "/home/abhinandan/PycharmProjects/todo/venv/lib/python3.5/site-packages/django/template/base.py", line 937, in render
    bit = node.render_annotated(context)
  File "/home/abhinandan/PycharmProjects/todo/venv/lib/python3.5/site-packages/django/template/base.py", line 904, in render_annotated
    return self.render(context)
  File "/home/abhinandan/PycharmProjects/todo/venv/lib/python3.5/site-packages/django/template/loader_tags.py", line 62, in render
    result = block.nodelist.render(context)
  File "/home/abhinandan/PycharmProjects/todo/venv/lib/python3.5/site-packages/django/template/base.py", line 937, in render
    bit = node.render_annotated(context)
  File "/home/abhinandan/PycharmProjects/todo/venv/lib/python3.5/site-packages/django/template/base.py", line 904, in render_annotated
    return self.render(context)
  File "/home/abhinandan/PycharmProjects/todo/venv/lib/python3.5/site-packages/django/template/defaulttags.py", line 309, in render
    return nodelist.render(context)
  File "/home/abhinandan/PycharmProjects/todo/venv/lib/python3.5/site-packages/django/template/base.py", line 937, in render
    bit = node.render_annotated(context)
  File "/home/abhinandan/PycharmProjects/todo/venv/lib/python3.5/site-packages/django/template/base.py", line 904, in render_annotated
    return self.render(context)
  File "/home/abhinandan/PycharmProjects/todo/venv/lib/python3.5/site-packages/django/template/defaulttags.py", line 443, in render
    url = reverse(view_name, args=args, kwargs=kwargs, current_app=current_app)
  File "/home/abhinandan/PycharmProjects/todo/venv/lib/python3.5/site-packages/django/urls/base.py", line 90, in reverse
    return iri_to_uri(resolver._reverse_with_prefix(view, prefix, *args, **kwargs))
  File "/home/abhinandan/PycharmProjects/todo/venv/lib/python3.5/site-packages/django/urls/resolvers.py", line 668, in _reverse_with_prefix
    raise NoReverseMatch(msg)
django.urls.exceptions.NoReverseMatch: Reverse for 'edit' with no arguments not found. 1 pattern(s) tried: ['edit\\/(?P<list_id>[^/]+)$']
[07/Aug/2019 09:54:28] "GET /edit/1 HTTP/1.1" 500 174807
[07/Aug/2019 09:55:41] "GET /edit/1 HTTP/1.1" 200 3125
[07/Aug/2019 09:55:41] "GET /static/css/my_css.css HTTP/1.1" 304 0
[07/Aug/2019 09:55:45] "POST /edit/1 HTTP/1.1" 302 0
[07/Aug/2019 09:55:45] "GET / HTTP/1.1" 200 4321
[07/Aug/2019 09:55:48] "GET /delete/1 HTTP/1.1" 302 0
[07/Aug/2019 09:55:48] "GET / HTTP/1.1" 200 3885
[07/Aug/2019 09:55:49] "GET /delete/4 HTTP/1.1" 302 0
[07/Aug/2019 09:55:49] "GET / HTTP/1.1" 200 3449
[07/Aug/2019 09:55:50] "GET /delete/2 HTTP/1.1" 302 0
[07/Aug/2019 09:55:50] "GET / HTTP/1.1" 200 2850
[07/Aug/2019 09:55:55] "POST / HTTP/1.1" 200 3415
[07/Aug/2019 09:55:57] "GET /edit/5 HTTP/1.1" 200 3125
[07/Aug/2019 09:56:00] "POST /edit/5 HTTP/1.1" 302 0
[07/Aug/2019 09:56:00] "GET / HTTP/1.1" 200 3413
[07/Aug/2019 09:56:02] "GET /cross_off/5 HTTP/1.1" 302 0
[07/Aug/2019 09:56:02] "GET / HTTP/1.1" 200 3028
[07/Aug/2019 09:56:05] "GET /delete/5 HTTP/1.1" 302 0
[07/Aug/2019 09:56:05] "GET / HTTP/1.1" 200 2850
[07/Aug/2019 09:56:13] "POST / HTTP/1.1" 200 3415
[07/Aug/2019 09:56:20] "POST / HTTP/1.1" 200 3852
[07/Aug/2019 09:56:24] "POST / HTTP/1.1" 200 4289
[07/Aug/2019 09:56:25] "GET /cross_off/7 HTTP/1.1" 302 0
[07/Aug/2019 09:56:25] "GET / HTTP/1.1" 200 3897
[07/Aug/2019 09:56:34] "GET / HTTP/1.1" 200 3897
